Workbook

Sheet 전체
A1: 품목 | B1: 구분 | C1: 2015-04-07~2015-05-06 | D1: 2015-05-07~2015-06-05 | E1: 2015-06-06~2015-07-05 | F1: 2015-07-06~2015-08-04 | G1: 2015-08-05~2015-09-03 | H1: 2015-09-04~2015-10-03 | I1: 2015-10-04~2015-11-02 | J1: 2015-11-03~2015-12-02 | K1: 2015-12-03~2016-01-01 | L1: 2016-01-02~2016-01-31 | M1: 2016-02-01~2016-03-01 | N1: 2016-03-02~2016-03-31 | O1: 2016-04-01~2016-04-30 | P1: 2016-05-01~2016-05-30 | Q1: 2016-05-31~2016-06-29 | R1: 2016-06-30~2016-07-29 | S1: 2016-07-30~2016-08-28 | T1: 2016-08-29~2016-09-27 | U1: 2016-09-28~2016-10-27 | V1: 2016-10-28~2016-11-26 | W1: 2016-11-27~2016-12-26 | X1: 2016-12-27~2017-01-25 | Y1: 2017-01-26~2017-02-24 | Z1: 2017-02-25~2017-03-26 | AA1: 2017-03-27~2017-04-25 | AB1: 2017-04-26~2017-05-25 | AC1: 2017-05-26~2017-06-24 | AD1: 2017-06-25~2017-07-24 | AE1: 2017-07-25~2017-08-23 | AF1: 2017-08-24~2017-09-22 | AG1: 2017-09-23~2017-10-22 | AH1: 2017-10-23~2017-11-21 | AI1: 2017-11-22~2017-12-21 | AJ1: 2017-12-22~2018-01-20 | AK1: 2018-01-21~2018-02-19 | AL1: 2018-02-20~2018-03-21 | AM1: 2018-03-22~2018-04-20 | AN1: 2018-04-21~2018-05-20 | AO1: 2018-05-21~2018-06-19 | AP1: 2018-06-20~2018-07-19 | AQ1: 2018-07-20~2018-08-18 | AR1: 2018-08-19~2018-09-17 | AS1: 2018-09-18~2018-10-17 | AT1: 2018-10-18~2018-11-16 | AU1: 2018-11-17~2018-12-16 | AV1: 2018-12-17~2019-01-15 | AW1: 2019-01-16~2019-02-14 | AX1: 2019-02-15~2019-03-16 | AY1: 2019-03-17~2019-04-15 | AZ1: 2019-04-16~2019-05-15 | BA1: 2019-05-16~2019-06-14 | BB1: 2019-06-15~2019-07-14 | BC1: 2019-07-15~2019-08-13 | BD1: 2019-08-14~2019-09-12 | BE1: 2019-09-13~2019-10-12 | BF1: 2019-10-13~2019-11-11 | BG1: 2019-11-12~2019-12-11 | BH1: 2019-12-12~2020-01-10 | BI1: 2020-01-11~2020-02-09 | BJ1: 2020-02-10~2020-03-10 | BK1: 2020-03-11~2020-04-09 | BL1: 2020-04-10~2020-05-09 | BM1: 2020-05-10~2020-06-08 | BN1: 2020-06-09~2020-07-08 | BO1: 2020-07-09~2020-08-07 | BP1: 2020-08-08~2020-09-06 | BQ1: 2020-09-07~2020-10-06 | BR1: 2020-10-07~2020-11-05 | BS1: 2020-11-06~2020-12-05 | BT1: 2020-12-06~2021-01-04 | BU1: 2021-01-05~2021-02-03 | BV1: 2021-02-04~2021-03-05 | BW1: 2021-03-06~2021-04-04 | BX1: 2021-04-05~2021-05-04 | BY1: 2021-05-05~2021-06-03 | BZ1: 2021-06-04~2021-07-03 | CA1: 2021-07-04~2021-08-02 | CB1: 2021-08-03~2021-09-01 | CC1: 2021-09-02~2021-10-01 | CD1: 2021-10-02~2021-10-31 | CE1: 2021-11-01~2021-11-30 | CF1: 2021-12-01~2021-12-30 | CG1: 2021-12-31~2022-01-29 | CH1: 2022-01-30~2022-02-28 | CI1: 2022-03-01~2022-03-30 | CJ1: 2022-03-31~2022-04-29 | CK1: 2022-04-30~2022-05-29 | CL1: 2022-05-30~2022-06-28 | CM1: 2022-06-29~2022-07-28 | CN1: 2022-07-29~2022-08-27 | CO1: 2022-08-28~2022-09-26 | CP1: 2022-09-27~2022-10-26 | CQ1: 2022-10-27~2022-11-25 | CR1: 2022-11-26~2022-12-25 | CS1: 2022-12-26~2023-01-24 | CT1: 2023-01-25~2023-02-23 | CU1: 2023-02-24~2023-03-25 | CV1: 2023-03-26~2023-04-24 | CW1: 2023-04-25~2023-05-24 | CX1: 2023-05-25~2023-06-23 | CY1: 2023-06-24~2023-07-23 | CZ1: 2023-07-24~2023-08-22 | DA1: 2023-08-23~2023-09-21 | DB1: 2023-09-22~2023-10-21 | DC1: 2023-10-22~2023-11-20 | DD1: 2023-11-21~2023-12-20 | DE1: 2023-12-21~2024-01-19 | DF1: 2024-01-20~2024-02-18 | DG1: 2024-02-19~2024-03-19 | DH1: 2024-03-20~2024-04-18 | DI1: 2024-04-19~2024-05-18 | DJ1: 2024-05-19~2024-06-17 | DK1: 2024-06-18~2024-07-17 | DL1: 2024-07-18~2024-08-16 | DM1: 2024-08-17~2024-09-15 | DN1: 2024-09-16~2024-10-15 | DO1: 2024-10-16~2024-11-14 | DP1: 2024-11-15~2024-12-14 | DQ1: 2024-12-15~2025-01-13 | DR1: 2025-01-14~2025-02-12 | DS1: 2025-02-13~2025-03-14 | DT1: 2025-03-15~2025-04-13 | DU1: 2025-04-14~2025-05-13 | DV1: 2025-05-14~2025-06-12 | DW1: 2025-06-13~2025-07-12 | DX1: 2025-07-13~2025-08-11 | DY1: 2025-08-12~2025-09-10 | DZ1: 2025-09-11~2025-10-10 | EA1: 2025-10-11~2025-11-09 | EB1: 2025-11-10~2025-12-09 | EC1: 2025-12-10~2026-01-08 | ED1: 2026-01-09~2026-02-07 | EE1: 2026-02-08~2026-03-09 | EF1: 2026-03-10~2026-04-08 | EG1: 2026-04-09~2026-05-08 | EH1: 2026-05-09~2026-06-07 | EI1: 2026-06-08~2026-07-07
A2: NAG(엔에이지, N-아세틸글루코사민, N-Acetylglucosamine) | B2: 검사건수 | C2: 0 | D2: 0 | E2: 0 | F2: 0 | G2: 0 | H2: 0 | I2: 0 | J2: 0 | K2: 0 | L2: 0 | M2: 0 | N2: 0 | O2: 0 | P2: 0 | Q2: 0 | R2: 0 | S2: 0 | T2: 0 | U2: 0 | V2: 0 | W2: 0 | X2: 0 | Y2: 0 | Z2: 0 | AA2: 0 | AB2: 0 | AC2: 0 | AD2: 0 | AE2: 0 | AF2: 0 | AG2: 0 | AH2: 0 | AI2: 0 | AJ2: 0 | AK2: 0 | AL2: 0 | AM2: 0 | AN2: 0 | AO2: 0 | AP2: 0 | AQ2: 0 | AR2: 0 | AS2: 0 | AT2: 0 | AU2: 0 | AV2: 0 | AW2: 0 | AX2: 0 | AY2: 0 | AZ2: 0 | BA2: 0 | BB2: 0 | BC2: 0 | BD2: 0 | BE2: 0 | BF2: 0 | BG2: 0 | BH2: 0 | BI2: 0 | BJ2: 0 | BK2: 0 | BL2: 0 | BM2: 0 | BN2: 0 | BO2: 0 | BP2: 0 | BQ2: 0 | BR2: 0 | BS2: 0 | BT2: 0 | BU2: 0 | BV2: 0 | BW2: 0 | BX2: 0 | BY2: 0 | BZ2: 0 | CA2: 0 | CB2: 0 | CC2: 0 | CD2: 0 | CE2: 0 | CF2: 0 | CG2: 0 | CH2: 0 | CI2: 0 | CJ2: 0 | CK2: 0 | CL2: 0 | CM2: 0 | CN2: 0 | CO2: 0 | CP2: 1 | CQ2: 0 | CR2: 0 | CS2: 0 | CT2: 0 | CU2: 0 | CV2: 0 | CW2: 0 | CX2: 0 | CY2: 0 | CZ2: 0 | DA2: 0 | DB2: 0 | DC2: 0 | DD2: 0 | DE2: 0 | DF2: 0 | DG2: 0 | DH2: 0 | DI2: 0 | DJ2: 0 | DK2: 0 | DL2: 0 | DM2: 0 | DN2: 0 | DO2: 0 | DP2: 0 | DQ2: 0 | DR2: 0 | DS2: 0 | DT2: 0 | DU2: 0 | DV2: 0 | DW2: 0 | DX2: 0 | DY2: 0 | DZ2: 0 | EA2: 0 | EB2: 0 | EC2: 0 | ED2: 0 | EE2: 0 | EF2: 0 | EG2: 0 | EH2: 0 | EI2: 0
A3: NAG(엔에이지, N-아세틸글루코사민, N-Acetylglucosamine) | B3: 검출건수 | C3: 0 | D3: 0 | E3: 0 | F3: 0 | G3: 0 | H3: 0 | I3: 0 | J3: 0 | K3: 0 | L3: 0 | M3: 0 | N3: 0 | O3: 0 | P3: 0 | Q3: 0 | R3: 0 | S3: 0 | T3: 0 | U3: 0 | V3: 0 | W3: 0 | X3: 0 | Y3: 0 | Z3: 0 | AA3: 0 | AB3: 0 | AC3: 0 | AD3: 0 | AE3: 0 | AF3: 0 | AG3: 0 | AH3: 0 | AI3: 0 | AJ3: 0 | AK3: 0 | AL3: 0 | AM3: 0 | AN3: 0 | AO3: 0 | AP3: 0 | AQ3: 0 | AR3: 0 | AS3: 0 | AT3: 0 | AU3: 0 | AV3: 0 | AW3: 0 | AX3: 0 | AY3: 0 | AZ3: 0 | BA3: 0 | BB3: 0 | BC3: 0 | BD3: 0 | BE3: 0 | BF3: 0 | BG3: 0 | BH3: 0 | BI3: 0 | BJ3: 0 | BK3: 0 | BL3: 0 | BM3: 0 | BN3: 0 | BO3: 0 | BP3: 0 | BQ3: 0 | BR3: 0 | BS3: 0 | BT3: 0 | BU3: 0 | BV3: 0 | BW3: 0 | BX3: 0 | BY3: 0 | BZ3: 0 | CA3: 0 | CB3: 0 | CC3: 0 | CD3: 0 | CE3: 0 | CF3: 0 | CG3: 0 | CH3: 0 | CI3: 0 | CJ3: 0 | CK3: 0 | CL3: 0 | CM3: 0 | CN3: 0 | CO3: 0 | CP3: 0 | CQ3: 0 | CR3: 0 | CS3: 0 | CT3: 0 | CU3: 0 | CV3: 0 | CW3: 0 | CX3: 0 | CY3: 0 | CZ3: 0 | DA3: 0 | DB3: 0 | DC3: 0 | DD3: 0 | DE3: 0 | DF3: 0 | DG3: 0 | DH3: 0 | DI3: 0 | DJ3: 0 | DK3: 0 | DL3: 0 | DM3: 0 | DN3: 0 | DO3: 0 | DP3: 0 | DQ3: 0 | DR3: 0 | DS3: 0 | DT3: 0 | DU3: 0 | DV3: 0 | DW3: 0 | DX3: 0 | DY3: 0 | DZ3: 0 | EA3: 0 | EB3: 0 | EC3: 0 | ED3: 0 | EE3: 0 | EF3: 0 | EG3: 0 | EH3: 0 | EI3: 0
A4: 가공김(조미김 또는 구운김) | B4: 검사건수 | C4: 0 | D4: 0 | E4: 0 | F4: 0 | G4: 0 | H4: 0 | I4: 0 | J4: 0 | K4: 0 | L4: 0 | M4: 0 | N4: 0 | O4: 0 | P4: 0 | Q4: 0 | R4: 0 | S4: 0 | T4: 0 | U4: 0 | V4: 0 | W4: 0 | X4: 0 | Y4: 0 | Z4: 0 | AA4: 0 | AB4: 0 | AC4: 0 | AD4: 0 | AE4: 0 | AF4: 0 | AG4: 0 | AH4: 0 | AI4: 0 | AJ4: 0 | AK4: 0 | AL4: 0 | AM4: 0 | AN4: 0 | AO4: 0 | AP4: 0 | AQ4: 0 | AR4: 0 | AS4: 0 | AT4: 0 | AU4: 0 | AV4: 0 | AW4: 0 | AX4: 0 | AY4: 0 | AZ4: 0 | BA4: 0 | BB4: 0 | BC4: 0 | BD4: 0 | BE4: 0 | BF4: 0 | BG4: 0 | BH4: 0 | BI4: 0 | BJ4: 0 | BK4: 0 | BL4: 0 | BM4: 0 | BN4: 0 | BO4: 0 | BP4: 0 | BQ4: 0 | BR4: 0 | BS4: 0 | BT4: 0 | BU4: 0 | BV4: 0 | BW4: 0 | BX4: 0 | BY4: 0 | BZ4: 0 | CA4: 0 | CB4: 0 | CC4: 0 | CD4: 0 | CE4: 0 | CF4: 0 | CG4: 0 | CH4: 0 | CI4: 0 | CJ4: 0 | CK4: 0 | CL4: 0 | CM4: 0 | CN4: 0 | CO4: 0 | CP4: 0 | CQ4: 0 | CR4: 0 | CS4: 0 | CT4: 0 | CU4: 0 | CV4: 0 | CW4: 0 | CX4: 0 | CY4: 0 | CZ4: 0 | DA4: 0 | DB4: 0 | DC4: 0 | DD4: 0 | DE4: 0 | DF4: 0 | DG4: 0 | DH4: 0 | DI4: 0 | DJ4: 0 | DK4: 0 | DL4: 0 | DM4: 0 | DN4: 0 | DO4: 0 | DP4: 0 | DQ4: 0 | DR4: 0 | DS4: 0 | DT4: 0 | DU4: 0 | DV4: 1 | DW4: 2 | DX4: 6 | DY4: 2 | DZ4: 1 | EA4: 1 | EB4: 3 | EC4: 5 | ED4: 1 | EE4: 3 | EF4: 4 | EG4: 4 | EH4: 21 | EI4: 9
A5: 가공김(조미김 또는 구운김) | B5: 검출건수 | C5: 0 | D5: 0 | E5: 0 | F5: 0 | G5: 0 | H5: 0 | I5: 0 | J5: 0 | K5: 0 | L5: 0 | M5: 0 | N5: 0 | O5: 0 | P5: 0 | Q5: 0 | R5: 0 | S5: 0 | T5: 0 | U5: 0 | V5: 0 | W5: 0 | X5: 0 | Y5: 0 | Z5: 0 | AA5: 0 | AB5: 0 | AC5: 0 | AD5: 0 | AE5: 0 | AF5: 0 | AG5: 0 | AH5: 0 | AI5: 0 | AJ5: 0 | AK5: 0 | AL5: 0 | AM5: 0 | AN5: 0 | AO5: 0 | AP5: 0 | AQ5: 0 | AR5: 0 | AS5: 0 | AT5: 0 | AU5: 0 | AV5: 0 | AW5: 0 | AX5: 0 | AY5: 0 | AZ5: 0 | BA5: 0 | BB5: 0 | BC5: 0 | BD5: 0 | BE5: 0 | BF5: 0 | BG5: 0 | BH5: 0 | BI5: 0 | BJ5: 0 | BK5: 0 | BL5: 0 | BM5: 0 | BN5: 0 | BO5: 0 | BP5: 0 | BQ5: 0 | BR5: 0 | BS5: 0 | BT5: 0 | BU5: 0 | BV5: 0 | BW5: 0 | BX5: 0 | BY5: 0 | BZ5: 0 | CA5: 0 | CB5: 0 | CC5: 0 | CD5: 0 | CE5: 0 | CF5: 0 | CG5: 0 | CH5: 0 | CI5: 0 | CJ5: 0 | CK5: 0 | CL5: 0 | CM5: 0 | CN5: 0 | CO5: 0 | CP5: 0 | CQ5: 0 | CR5: 0 | CS5: 0 | CT5: 0 | CU5: 0 | CV5: 0 | CW5: 0 | CX5: 0 | CY5: 0 | CZ5: 0 | DA5: 0 | DB5: 0 | DC5: 0 | DD5: 0 | DE5: 0 | DF5: 0 | DG5: 0 | DH5: 0 | DI5: 0 | DJ5: 0 | DK5: 0 | DL5: 0 | DM5: 0 | DN5: 0 | DO5: 0 | DP5: 0 | DQ5: 0 | DR5: 0 | DS5: 0 | DT5: 0 | DU5: 0 | DV5: 0 | DW5: 0 | DX5: 0 | DY5: 0 | DZ5: 0 | EA5: 0 | EB5: 0 | EC5: 0 | ED5: 0 | EE5: 0 | EF5: 0 | EG5: 0 | EH5: 0 | EI5: 0
A6: 가공두부 | B6: 검사건수 | C6: 0 | D6: 0 | E6: 0 | F6: 0 | G6: 0 | H6: 0 | I6: 0 | J6: 0 | K6: 0 | L6: 0 | M6: 0 | N6: 2 | O6: 2 | P6: 0 | Q6: 1 | R6: 1 | S6: 1 | T6: 1 | U6: 1 | V6: 2 | W6: 1 | X6: 1 | Y6: 2 | Z6: 1 | AA6: 1 | AB6: 2 | AC6: 1 | AD6: 1 | AE6: 2 | AF6: 6 | AG6: 1 | AH6: 2 | AI6: 1 | AJ6: 1 | AK6: 1 | AL6: 1 | AM6: 1 | AN6: 3 | AO6: 1 | AP6: 1 | AQ6: 3 | AR6: 3 | AS6: 2 | AT6: 4 | AU6: 1 | AV6: 1 | AW6: 3 | AX6: 1 | AY6: 2 | AZ6: 2 | BA6: 1 | BB6: 1 | BC6: 2 | BD6: 1 | BE6: 1 | BF6: 2 | BG6: 1 | BH6: 1 | BI6: 1 | BJ6: 2 | BK6: 1 | BL6: 1 | BM6: 3 | BN6: 1 | BO6: 1 | BP6: 1 | BQ6: 1 | BR6: 1 | BS6: 2 | BT6: 0 | BU6: 1 | BV6: 1 | BW6: 0 | BX6: 0 | BY6: 0 | BZ6: 0 | CA6: 0 | CB6: 0 | CC6: 0 | CD6: 0 | CE6: 0 | CF6: 0 | CG6: 0 | CH6: 0 | CI6: 0 | CJ6: 0 | CK6: 0 | CL6: 0 | CM6: 0 | CN6: 0 | CO6: 0 | CP6: 0 | CQ6: 0 | CR6: 0 | CS6: 0 | CT6: 0 | CU6: 1 | CV6: 0 | CW6: 0 | CX6: 0 | CY6: 0 | CZ6: 0 | DA6: 0 | DB6: 0 | DC6: 0 | DD6: 0 | DE6: 1 | DF6: 0 | DG6: 0 | DH6: 1 | DI6: 0 | DJ6: 0 | DK6: 0 | DL6: 0 | DM6: 0 | DN6: 0 | DO6: 0 | DP6: 0 | DQ6: 0 | DR6: 2 | DS6: 2 | DT6: 0 | DU6: 0 | DV6: 1 | DW6: 0 | DX6: 0 | DY6: 0 | DZ6: 4 | EA6: 0 | EB6: 0 | EC6: 0 | ED6: 0 | EE6: 2 | EF6: 0 | EG6: 0 | EH6: 0 | EI6: 0
A7: 가공두부 | B7: 검출건수 | C7: 0 | D7: 0 | E7: 0 | F7: 0 | G7: 0 | H7: 0 | I7: 0 | J7: 0 | K7: 0 | L7: 0 | M7: 0 | N7: 0 | O7: 0 | P7: 0 | Q7: 0 | R7: 0 | S7: 0 | T7: 0 | U7: 0 | V7: 0 | W7: 0 | X7: 0 | Y7: 0 | Z7: 0 | AA7: 0 | AB7: 0 | AC7: 0 | AD7: 0 | AE7: 0 | AF7: 0 | AG7: 0 | AH7: 0 | AI7: 0 | AJ7: 0 | AK7: 0 | AL7: 0 | AM7: 0 | AN7: 0 | AO7: 0 | AP7: 0 | AQ7: 0 | AR7: 0 | AS7: 0 | AT7: 0 | AU7: 0 | AV7: 0 | AW7: 0 | AX7: 0 | AY7: 0 | AZ7: 0 | BA7: 0 | BB7: 0 | BC7: 0 | BD7: 0 | BE7: 0 | BF7: 0 | BG7: 0 | BH7: 0 | BI7: 0 | BJ7: 0 | BK7: 0 | BL7: 0 | BM7: 0 | BN7: 0 | BO7: 0 | BP7: 0 | BQ7: 0 | BR7: 0 | BS7: 0 | BT7: 0 | BU7: 0 | BV7: 0 | BW7: 0 | BX7: 0 | BY7: 0 | BZ7: 0 | CA7: 0 | CB7: 0 | CC7: 0 | CD7: 0 | CE7: 0 | CF7: 0 | CG7: 0 | CH7: 0 | CI7: 0 | CJ7: 0 | CK7: 0 | CL7: 0 | CM7: 0 | CN7: 0 | CO7: 0 | CP7: 0 | CQ7: 0 | CR7: 0 | CS7: 0 | CT7: 0 | CU7: 0 | CV7: 0 | CW7: 0 | CX7: 0 | CY7: 0 | CZ7: 0 | DA7: 0 | DB7: 0 | DC7: 0 | DD7: 0 | DE7: 0 | DF7: 0 | DG7: 0 | DH7: 0 | DI7: 0 | DJ7: 0 | DK7: 0 | DL7: 0 | DM7: 0 | DN7: 0 | DO7: 0 | DP7: 0 | DQ7: 0 | DR7: 0 | DS7: 0 | DT7: 0 | DU7: 0 | DV7: 0 | DW7: 0 | DX7: 0 | DY7: 0 | DZ7: 0 | EA7: 0 | EB7: 0 | EC7: 0 | ED7: 0 | EE7: 0 | EF7: 0 | EG7: 0 | EH7: 0 | EI7: 0
A8: 가공유류 | B8: 검사건수 | C8: 0 | D8: 0 | E8: 0 | F8: 0 | G8: 0 | H8: 0 | I8: 0 | J8: 0 | K8: 0 | L8: 0 | M8: 0 | N8: 0 | O8: 1 | P8: 4 | Q8: 12 | R8: 68 | S8: 22 | T8: 19 | U8: 24 | V8: 23 | W8: 23 | X8: 25 | Y8: 36 | Z8: 56 | AA8: 59 | AB8: 51 | AC8: 70 | AD8: 53 | AE8: 78 | AF8: 67 | AG8: 57 | AH8: 80 | AI8: 59 | AJ8: 30 | AK8: 37 | AL8: 30 | AM8: 43 | AN8: 46 | AO8: 48 | AP8: 41 | AQ8: 51 | AR8: 77 | AS8: 69 | AT8: 67 | AU8: 47 | AV8: 44 | AW8: 41 | AX8: 45 | AY8: 71 | AZ8: 58 | BA8: 58 | BB8: 64 | BC8: 70 | BD8: 62 | BE8: 68 | BF8: 68 | BG8: 69 | BH8: 68 | BI8: 63 | BJ8: 82 | BK8: 101 | BL8: 86 | BM8: 113 | BN8: 113 | BO8: 77 | BP8: 96 | BQ8: 69 | BR8: 101 | BS8: 81 | BT8: 74 | BU8: 78 | BV8: 72 | BW8: 64 | BX8: 88 | BY8: 82 | BZ8: 96 | CA8: 83 | CB8: 82 | CC8: 65 | CD8: 112 | CE8: 80 | CF8: 81 | CG8: 75 | CH8: 63 | CI8: 83 | CJ8: 73 | CK8: 70 | CL8: 80 | CM8: 133 | CN8: 68 | CO8: 87 | CP8: 115 | CQ8: 85 | CR8: 61 | CS8: 54 | CT8: 75 | CU8: 78 | CV8: 77 | CW8: 77 | CX8: 88 | CY8: 98 | CZ8: 81 | DA8: 88 | DB8: 78 | DC8: 100 | DD8: 65 | DE8: 65 | DF8: 61 | DG8: 81 | DH8: 89 | DI8: 81 | DJ8: 75 | DK8: 71 | DL8: 105 | DM8: 59 | DN8: 61 | DO8: 89 | DP8: 65 | DQ8: 67 | DR8: 63 | DS8: 72 | DT8: 81 | DU8: 84 | DV8: 80 | DW8: 85 | DX8: 92 | DY8: 80 | DZ8: 59 | EA8: 81 | EB8: 70 | EC8: 59 | ED8: 63 | EE8: 72 | EF8: 88 | EG8: 111 | EH8: 69 | EI8: 36
A9: 가공유류 | B9: 검출건수 | C9: 0 | D9: 0 | E9: 0 | F9: 0 | G9: 0 | H9: 0 | I9: 0 | J9: 0 | K9: 0 | L9: 0 | M9: 0 | N9: 0 | O9: 0 | P9: 0 | Q9: 0 | R9: 0 | S9: 0 | T9: 0 | U9: 0 | V9: 0 | W9: 0 | X9: 0 | Y9: 0 | Z9: 0 | AA9: 0 | AB9: 0 | AC9: 0 | AD9: 0 | AE9: 0 | AF9: 0 | AG9: 0 | AH9: 0 | AI9: 0 | AJ9: 0 | AK9: 0 | AL9: 0 | AM9: 0 | AN9: 0 | AO9: 0 | AP9: 0 | AQ9: 0 | AR9: 0 | AS9: 0 | AT9: 0 | AU9: 0 | AV9: 0 | AW9: 0 | AX9: 0 | AY9: 0 | AZ9: 0 | BA9: 0 | BB9: 0 | BC9: 0 | BD9: 0 | BE9: 0 | BF9: 0 | BG9: 0 | BH9: 0 | BI9: 0 | BJ9: 0 | BK9: 0 | BL9: 0 | BM9: 0 | BN9: 0 | BO9: 0 | BP9: 0 | BQ9: 0 | BR9: 0 | BS9: 0 | BT9: 0 | BU9: 0 | BV9: 0 | BW9: 0 | BX9: 0 | BY9: 0 | BZ9: 0 | CA9: 0 | CB9: 0 | CC9: 0 | CD9: 0 | CE9: 0 | CF9: 0 | CG9: 0 | CH9: 0 | CI9: 0 | CJ9: 0 | CK9: 0 | CL9: 0 | CM9: 0 | CN9: 0 | CO9: 0 | CP9: 0 | CQ9: 0 | CR9: 0 | CS9: 0 | CT9: 0 | CU9: 0 | CV9: 0 | CW9: 0 | CX9: 0 | CY9: 0 | CZ9: 0 | DA9: 0 | DB9: 0 | DC9: 0 | DD9: 0 | DE9: 0 | DF9: 0 | DG9: 0 | DH9: 0 | DI9: 0 | DJ9: 0 | DK9: 0 | DL9: 0 | DM9: 0 | DN9: 0 | DO9: 0 | DP9: 0 | DQ9: 0 | DR9: 0 | DS9: 0 | DT9: 0 | DU9: 0 | DV9: 0 | DW9: 0 | DX9: 0 | DY9: 0 | DZ9: 0 | EA9: 0 | EB9: 0 | EC9: 0 | ED9: 0 | EE9: 0 | EF9: 0 | EG9: 0 | EH9: 0 | EI9: 0
A10: 가금류 | B10: 검사건수 | C10: 0 | D10: 0 | E10: 0 | F10: 0 | G10: 0 | H10: 0 | I10: 0 | J10: 0 | K10: 0 | L10: 0 | M10: 0 | N10: 0 | O10: 0 | P10: 0 | Q10: 0 | R10: 0 | S10: 0 | T10: 0 | U10: 0 | V10: 0 | W10: 0 | X10: 0 | Y10: 0 | Z10: 0 | AA10: 2 | AB10: 0 | AC10: 0 | AD10: 0 | AE10: 1 | AF10: 0 | AG10: 0 | AH10: 0 | AI10: 0 | AJ10: 0 | AK10: 0 | AL10: 0 | AM10: 0 | AN10: 0 | AO10: 0 | AP10: 0 | AQ10: 0 | AR10: 0 | AS10: 0 | AT10: 0 | AU10: 0 | AV10: 0 | AW10: 0 | AX10: 0 | AY10: 0 | AZ10: 0 | BA10: 0 | BB10: 0 | BC10: 0 | BD10: 0 | BE10: 0 | BF10: 2 | BG10: 0 | BH10: 0 | BI10: 0 | BJ10: 0 | BK10: 0 | BL10: 0 | BM10: 1 | BN10: 0 | BO10: 0 | BP10: 2 | BQ10: 2 | BR10: 2 | BS10: 0 | BT10: 0 | BU10: 0 | BV10: 2 | BW10: 2 | BX10: 0 | BY10: 0 | BZ10: 0 | CA10: 0 | CB10: 3 | CC10: 2 | CD10: 5 | CE10: 3 | CF10: 0 | CG10: 0 | CH10: 3 | CI10: 1 | CJ10: 0 | CK10: 0 | CL10: 0 | CM10: 0 | CN10: 0 | CO10: 0 | CP10: 0 | CQ10: 0 | CR10: 0 | CS10: 0 | CT10: 0 | CU10: 3 | CV10: 0 | CW10: 0 | CX10: 0 | CY10: 2 | CZ10: 0 | DA10: 0 | DB10: 0 | DC10: 2 | DD10: 0 | DE10: 3 | DF10: 0 | DG10: 0 | DH10: 3 | DI10: 0 | DJ10: 4 | DK10: 0 | DL10: 0 | DM10: 0 | DN10: 0 | DO10: 4 | DP10: 2 | DQ10: 1 | DR10: 0 | DS10: 0 | DT10: 1 | DU10: 0 | DV10: 3 | DW10: 0 | DX10: 0 | DY10: 2 | DZ10: 1 | EA10: 2 | EB10: 0 | EC10: 1 | ED10: 0 | EE10: 1 | EF10: 3 | EG10: 0 | EH10: 3 | EI10: 0
A11: 가금류 | B11: 검출건수 | C11: 0 | D11: 0 | E11: 0 | F11: 0 | G11: 0 | H11: 0 | I11: 0 | J11: 0 | K11: 0 | L11: 0 | M11: 0 | N11: 0 | O11: 0 | P11: 0 | Q11: 0 | R11: 0 | S11: 0 | T11: 0 | U11: 0 | V11: 0 | W11: 0 | X11: 0 | Y11: 0 | Z11: 0 | AA11: 0 | AB11: 0 | AC11: 0 | AD11: 0 | AE11: 0 | AF11: 0 | AG11: 0 | AH11: 0 | AI11: 0 | AJ11: 0 | AK11: 0 | AL11: 0 | AM11: 0 | AN11: 0 | AO11: 0 | AP11: 0 | AQ11: 0 | AR11: 0 | AS11: 0 | AT11: 0 | AU11: 0 | AV11: 0 | AW11: 0 | AX11: 0 | AY11: 0 | AZ11: 0 | BA11: 0 | BB11: 0 | BC11: 0 | BD11: 0 | BE11: 0 | BF11: 0 | BG11: 0 | BH11: 0 | BI11: 0 | BJ11: 0 | BK11: 0 | BL11: 0 | BM11: 0 | BN11: 0 | BO11: 0 | BP11: 0 | BQ11: 0 | BR11: 0 | BS11: 0 | BT11: 0 | BU11: 0 | BV11: 0 | BW11: 0 | BX11: 0 | BY11: 0 | BZ11: 0 | CA11: 0 | CB11: 0 | CC11: 0 | CD11: 0 | CE11: 0 | CF11: 0 | CG11: 0 | CH11: 0 | CI11: 0 | CJ11: 0 | CK11: 0 | CL11: 0 | CM11: 0 | CN11: 0 | CO11: 0 | CP11: 0 | CQ11: 0 | CR11: 0 | CS11: 0 | CT11: 0 | CU11: 0 | CV11: 0 | CW11: 0 | CX11: 0 | CY11: 0 | CZ11: 0 | DA11: 0 | DB11: 0 | DC11: 0 | DD11: 0 | DE11: 0 | DF11: 0 | DG11: 0 | DH11: 0 | DI11: 0 | DJ11: 0 | DK11: 0 | DL11: 0 | DM11: 0 | DN11: 0 | DO11: 0 | DP11: 0 | DQ11: 0 | DR11: 0 | DS11: 0 | DT11: 0 | DU11: 0 | DV11: 0 | DW11: 0 | DX11: 0 | DY11: 0 | DZ11: 0 | EA11: 0 | EB11: 0 | EC11: 0 | ED11: 0 | EE11: 0 | EF11: 0 | EG11: 0 | EH11: 0 | EI11: 0
A12: 가르시니아캄보지아 추출물 | B12: 검사건수 | C12: 0 | D12: 0 | E12: 0 | F12: 0 | G12: 0 | H12: 0 | I12: 0 | J12: 0 | K12: 0 | L12: 0 | M12: 0 | N12: 0 | O12: 0 | P12: 0 | Q12: 0 | R12: 0 | S12: 0 | T12: 0 | U12: 0 | V12: 0 | W12: 0 | X12: 0 | Y12: 0 | Z12: 0 | AA12: 0 | AB12: 0 | AC12: 0 | AD12: 0 | AE12: 0 | AF12: 1 | AG12: 0 | AH12: 0 | AI12: 0 | AJ12: 0 | AK12: 0 | AL12: 0 | AM12: 0 | AN12: 0 | AO12: 0 | AP12: 0 | AQ12: 0 | AR12: 0 | AS12: 0 | AT12: 0 | AU12: 0 | AV12: 0 | AW12: 0 | AX12: 0 | AY12: 0 | AZ12: 0 | BA12: 4 | BB12: 0 | BC12: 0 | BD12: 0 | BE12: 0 | BF12: 2 | BG12: 0 | BH12: 0 | BI12: 0 | BJ12: 0 | BK12: 0 | BL12: 0 | BM12: 0 | BN12: 0 | BO12: 0 | BP12: 0 | BQ12: 0 | BR12: 0 | BS12: 0 | BT12: 0 | BU12: 0 | BV12: 0 | BW12: 0 | BX12: 0 | BY12: 0 | BZ12: 0 | CA12: 0 | CB12: 0 | CC12: 0 | CD12: 0 | CE12: 0 | CF12: 0 | CG12: 0 | CH12: 0 | CI12: 0 | CJ12: 0 | CK12: 0 | CL12: 0 | CM12: 0 | CN12: 0 | CO12: 0 | CP12: 0 | CQ12: 0 | CR12: 0 | CS12: 0 | CT12: 1 | CU12: 0 | CV12: 0 | CW12: 0 | CX12: 0 | CY12: 0 | CZ12: 0 | DA12: 0 | DB12: 0 | DC12: 0 | DD12: 0 | DE12: 0 | DF12: 0 | DG12: 0 | DH12: 0 | DI12: 0 | DJ12: 0 | DK12: 0 | DL12: 0 | DM12: 0 | DN12: 0 | DO12: 0 | DP12: 0 | DQ12: 0 | DR12: 0 | DS12: 0 | DT12: 0 | DU12: 0 | DV12: 0 | DW12: 0 | DX12: 0 | DY12: 0 | DZ12: 0 | EA12: 0 | EB12: 0 | EC12: 0 | ED12: 0 | EE12: 0 | EF12: 0 | EG12: 0 | EH12: 0 | EI12: 0
A13: 가르시니아캄보지아 추출물 | B13: 검출건수 | C13: 0 | D13: 0 | E13: 0 | F13: 0 | G13: 0 | H13: 0 | I13: 0 | J13: 0 | K13: 0 | L13: 0 | M13: 0 | N13: 0 | O13: 0 | P13: 0 | Q13: 0 | R13: 0 | S13: 0 | T13: 0 | U13: 0 | V13: 0 | W13: 0 | X13: 0 | Y13: 0 | Z13: 0 | AA13: 0 | AB13: 0 | AC13: 0 | AD13: 0 | AE13: 0 | AF13: 0 | AG13: 0 | AH13: 0 | AI13: 0 | AJ13: 0 | AK13: 0 | AL13: 0 | AM13: 0 | AN13: 0 | AO13: 0 | AP13: 0 | AQ13: 0 | AR13: 0 | AS13: 0 | AT13: 0 | AU13: 0 | AV13: 0 | AW13: 0 | AX13: 0 | AY13: 0 | AZ13: 0 | BA13: 0 | BB13: 0 | BC13: 0 | BD13: 0 | BE13: 0 | BF13: 0 | BG13: 0 | BH13: 0 | BI13: 0 | BJ13: 0 | BK13: 0 | BL13: 0 | BM13: 0 | BN13: 0 | BO13: 0 | BP13: 0 | BQ13: 0 | BR13: 0 | BS13: 0 | BT13: 0 | BU13: 0 | BV13: 0 | BW13: 0 | BX13: 0 | BY13: 0 | BZ13: 0 | CA13: 0 | CB13: 0 | CC13: 0 | CD13: 0 | CE13: 0 | CF13: 0 | CG13: 0 | CH13: 0 | CI13: 0 | CJ13: 0 | CK13: 0 | CL13: 0 | CM13: 0 | CN13: 0 | CO13: 0 | CP13: 0 | CQ13: 0 | CR13: 0 | CS13: 0 | CT13: 0 | CU13: 0 | CV13: 0 | CW13: 0 | CX13: 0 | CY13: 0 | CZ13: 0 | DA13: 0 | DB13: 0 | DC13: 0 | DD13: 0 | DE13: 0 | DF13: 0 | DG13: 0 | DH13: 0 | DI13: 0 | DJ13: 0 | DK13: 0 | DL13: 0 | DM13: 0 | DN13: 0 | DO13: 0 | DP13: 0 | DQ13: 0 | DR13: 0 | DS13: 0 | DT13: 0 | DU13: 0 | DV13: 0 | DW13: 0 | DX13: 0 | DY13: 0 | DZ13: 0 | EA13: 0 | EB13: 0 | EC13: 0 | ED13: 0 | EE13: 0 | EF13: 0 | EG13: 0 | EH13: 0 | EI13: 0
... A435: 효소처리스테비아 | B435: 검출건수 | C435: 0 | D435: 0 | E435: 0 | F435: 0 | G435: 0 | H435: 0 | I435: 0 | J435: 0 | K435: 0 | L435: 0 | M435: 0 | N435: 0 | O435: 0 | P435: 0 | Q435: 0 | R435: 0 | S435: 0 | T435: 0 | U435: 0 | V435: 0 | W435: 0 | X435: 0 | Y435: 0 | Z435: 0 | AA435: 0 | AB435: 0 | AC435: 0 | AD435: 0 | AE435: 0 | AF435: 0 | AG435: 0 | AH435: 0 | AI435: 0 | AJ435: 0 | AK435: 0 | AL435: 0 | AM435: 0 | AN435: 0 | AO435: 0 | AP435: 0 | AQ435: 0 | AR435: 0 | AS435: 0 | AT435: 0 | AU435: 0 | AV435: 0 | AW435: 0 | AX435: 0 | AY435: 0 | AZ435: 0 | BA435: 0 | BB435: 0 | BC435: 0 | BD435: 0 | BE435: 0 | BF435: 0 | BG435: 0 | BH435: 0 | BI435: 0 | BJ435: 0 | BK435: 0 | BL435: 0 | BM435: 0 | BN435: 0 | BO435: 0 | BP435: 0 | BQ435: 0 | BR435: 0 | BS435: 0 | BT435: 0 | BU435: 0 | BV435: 0 | BW435: 0 | BX435: 0 | BY435: 0 | BZ435: 0 | CA435: 0 | CB435: 0 | CC435: 0 | CD435: 0 | CE435: 0 | CF435: 0 | CG435: 0 | CH435: 0 | CI435: 0 | CJ435: 0 | CK435: 0 | CL435: 0 | CM435: 0 | CN435: 0 | CO435: 0 | CP435: 0 | CQ435: 0 | CR435: 0 | CS435: 0 | CT435: 0 | CU435: 0 | CV435: 0 | CW435: 0 | CX435: 0 | CY435: 0 | CZ435: 0 | DA435: 0 | DB435: 0 | DC435: 0 | DD435: 0 | DE435: 0 | DF435: 0 | DG435: 0 | DH435: 0 | DI435: 0 | DJ435: 0 | DK435: 0 | DL435: 0 | DM435: 0 | DN435: 0 | DO435: 0 | DP435: 0 | DQ435: 0 | DR435: 0 | DS435: 0 | DT435: 0 | DU435: 0 | DV435: 0 | DW435: 0 | DX435: 0 | DY435: 0 | DZ435: 0 | EA435: 0 | EB435: 0 | EC435: 0 | ED435: 0 | EE435: 0 | EF435: 0 | EG435: 0 | EH435: 0 | EI435: 0

Sheet 검사건수
A1: 품목 | B1: 구분 | C1: 2015-04-07~2015-05-06 | D1: 2015-05-07~2015-06-05 | E1: 2015-06-06~2015-07-05 | F1: 2015-07-06~2015-08-04 | G1: 2015-08-05~2015-09-03 | H1: 2015-09-04~2015-10-03 | I1: 2015-10-04~2015-11-02 | J1: 2015-11-03~2015-12-02 | K1: 2015-12-03~2016-01-01 | L1: 2016-01-02~2016-01-31 | M1: 2016-02-01~2016-03-01 | N1: 2016-03-02~2016-03-31 | O1: 2016-04-01~2016-04-30 | P1: 2016-05-01~2016-05-30 | Q1: 2016-05-31~2016-06-29 | R1: 2016-06-30~2016-07-29 | S1: 2016-07-30~2016-08-28 | T1: 2016-08-29~2016-09-27 | U1: 2016-09-28~2016-10-27 | V1: 2016-10-28~2016-11-26 | W1: 2016-11-27~2016-12-26 | X1: 2016-12-27~2017-01-25 | Y1: 2017-01-26~2017-02-24 | Z1: 2017-02-25~2017-03-26 | AA1: 2017-03-27~2017-04-25 | AB1: 2017-04-26~2017-05-25 | AC1: 2017-05-26~2017-06-24 | AD1: 2017-06-25~2017-07-24 | AE1: 2017-07-25~2017-08-23 | AF1: 2017-08-24~2017-09-22 | AG1: 2017-09-23~2017-10-22 | AH1: 2017-10-23~2017-11-21 | AI1: 2017-11-22~2017-12-21 | AJ1: 2017-12-22~2018-01-20 | AK1: 2018-01-21~2018-02-19 | AL1: 2018-02-20~2018-03-21 | AM1: 2018-03-22~2018-04-20 | AN1: 2018-04-21~2018-05-20 | AO1: 2018-05-21~2018-06-19 | AP1: 2018-06-20~2018-07-19 | AQ1: 2018-07-20~2018-08-18 | AR1: 2018-08-19~2018-09-17 | AS1: 2018-09-18~2018-10-17 | AT1: 2018-10-18~2018-11-16 | AU1: 2018-11-17~2018-12-16 | AV1: 2018-12-17~2019-01-15 | AW1: 2019-01-16~2019-02-14 | AX1: 2019-02-15~2019-03-16 | AY1: 2019-03-17~2019-04-15 | AZ1: 2019-04-16~2019-05-15 | BA1: 2019-05-16~2019-06-14 | BB1: 2019-06-15~2019-07-14 | BC1: 2019-07-15~2019-08-13 | BD1: 2019-08-14~2019-09-12 | BE1: 2019-09-13~2019-10-12 | BF1: 2019-10-13~2019-11-11 | BG1: 2019-11-12~2019-12-11 | BH1: 2019-12-12~2020-01-10 | BI1: 2020-01-11~2020-02-09 | BJ1: 2020-02-10~2020-03-10 | BK1: 2020-03-11~2020-04-09 | BL1: 2020-04-10~2020-05-09 | BM1: 2020-05-10~2020-06-08 | BN1: 2020-06-09~2020-07-08 | BO1: 2020-07-09~2020-08-07 | BP1: 2020-08-08~2020-09-06 | BQ1: 2020-09-07~2020-10-06 | BR1: 2020-10-07~2020-11-05 | BS1: 2020-11-06~2020-12-05 | BT1: 2020-12-06~2021-01-04 | BU1: 2021-01-05~2021-02-03 | BV1: 2021-02-04~2021-03-05 | BW1: 2021-03-06~2021-04-04 | BX1: 2021-04-05~2021-05-04 | BY1: 2021-05-05~2021-06-03 | BZ1: 2021-06-04~2021-07-03 | CA1: 2021-07-04~2021-08-02 | CB1: 2021-08-03~2021-09-01 | CC1: 2021-09-02~2021-10-01 | CD1: 2021-10-02~2021-10-31 | CE1: 2021-11-01~2021-11-30 | CF1: 2021-12-01~2021-12-30 | CG1: 2021-12-31~2022-01-29 | CH1: 2022-01-30~2022-02-28 | CI1: 2022-03-01~2022-03-30 | CJ1: 2022-03-31~2022-04-29 | CK1: 2022-04-30~2022-05-29 | CL1: 2022-05-30~2022-06-28 | CM1: 2022-06-29~2022-07-28 | CN1: 2022-07-29~2022-08-27 | CO1: 2022-08-28~2022-09-26 | CP1: 2022-09-27~2022-10-26 | CQ1: 2022-10-27~2022-11-25 | CR1: 2022-11-26~2022-12-25 | CS1: 2022-12-26~2023-01-24 | CT1: 2023-01-25~2023-02-23 | CU1: 2023-02-24~2023-03-25 | CV1: 2023-03-26~2023-04-24 | CW1: 2023-04-25~2023-05-24 | CX1: 2023-05-25~2023-06-23 | CY1: 2023-06-24~2023-07-23 | CZ1: 2023-07-24~2023-08-22 | DA1: 2023-08-23~2023-09-21 | DB1: 2023-09-22~2023-10-21 | DC1: 2023-10-22~2023-11-20 | DD1: 2023-11-21~2023-12-20 | DE1: 2023-12-21~2024-01-19 | DF1: 2024-01-20~2024-02-18 | DG1: 2024-02-19~2024-03-19 | DH1: 2024-03-20~2024-04-18 | DI1: 2024-04-19~2024-05-18 | DJ1: 2024-05-19~2024-06-17 | DK1: 2024-06-18~2024-07-17 | DL1: 2024-07-18~2024-08-16 | DM1: 2024-08-17~2024-09-15 | DN1: 2024-09-16~2024-10-15 | DO1: 2024-10-16~2024-11-14 | DP1: 2024-11-15~2024-12-14 | DQ1: 2024-12-15~2025-01-13 | DR1: 2025-01-14~2025-02-12 | DS1: 2025-02-13~2025-03-14 | DT1: 2025-03-15~2025-04-13 | DU1: 2025-04-14~2025-05-13 | DV1: 2025-05-14~2025-06-12 | DW1: 2025-06-13~2025-07-12 | DX1: 2025-07-13~2025-08-11 | DY1: 2025-08-12~2025-09-10 | DZ1: 2025-09-11~2025-10-10 | EA1: 2025-10-11~2025-11-09 | EB1: 2025-11-10~2025-12-09 | EC1: 2025-12-10~2026-01-08 | ED1: 2026-01-09~2026-02-07 | EE1: 2026-02-08~2026-03-09 | EF1: 2026-03-10~2026-04-08 | EG1: 2026-04-09~2026-05-08 | EH1: 2026-05-09~2026-06-07 | EI1: 2026-06-08~2026-07-07
A2: NAG(엔에이지, N-아세틸글루코사민, N-Acetylglucosamine) | B2: 검사건수 | C2: 0 | D2: 0 | E2: 0 | F2: 0 | G2: 0 | H2: 0 | I2: 0 | J2: 0 | K2: 0 | L2: 0 | M2: 0 | N2: 0 | O2: 0 | P2: 0 | Q2: 0 | R2: 0 | S2: 0 | T2: 0 | U2: 0 | V2: 0 | W2: 0 | X2: 0 | Y2: 0 | Z2: 0 | AA2: 0 | AB2: 0 | AC2: 0 | AD2: 0 | AE2: 0 | AF2: 0 | AG2: 0 | AH2: 0 | AI2: 0 | AJ2: 0 | AK2: 0 | AL2: 0 | AM2: 0 | AN2: 0 | AO2: 0 | AP2: 0 | AQ2: 0 | AR2: 0 | AS2: 0 | AT2: 0 | AU2: 0 | AV2: 0 | AW2: 0 | AX2: 0 | AY2: 0 | AZ2: 0 | BA2: 0 | BB2: 0 | BC2: 0 | BD2: 0 | BE2: 0 | BF2: 0 | BG2: 0 | BH2: 0 | BI2: 0 | BJ2: 0 | BK2: 0 | BL2: 0 | BM2: 0 | BN2: 0 | BO2: 0 | BP2: 0 | BQ2: 0 | BR2: 0 | BS2: 0 | BT2: 0 | BU2: 0 | BV2: 0 | BW2: 0 | BX2: 0 | BY2: 0 | BZ2: 0 | CA2: 0 | CB2: 0 | CC2: 0 | CD2: 0 | CE2: 0 | CF2: 0 | CG2: 0 | CH2: 0 | CI2: 0 | CJ2: 0 | CK2: 0 | CL2: 0 | CM2: 0 | CN2: 0 | CO2: 0 | CP2: 1 | CQ2: 0 | CR2: 0 | CS2: 0 | CT2: 0 | CU2: 0 | CV2: 0 | CW2: 0 | CX2: 0 | CY2: 0 | CZ2: 0 | DA2: 0 | DB2: 0 | DC2: 0 | DD2: 0 | DE2: 0 | DF2: 0 | DG2: 0 | DH2: 0 | DI2: 0 | DJ2: 0 | DK2: 0 | DL2: 0 | DM2: 0 | DN2: 0 | DO2: 0 | DP2: 0 | DQ2: 0 | DR2: 0 | DS2: 0 | DT2: 0 | DU2: 0 | DV2: 0 | DW2: 0 | DX2: 0 | DY2: 0 | DZ2: 0 | EA2: 0 | EB2: 0 | EC2: 0 | ED2: 0 | EE2: 0 | EF2: 0 | EG2: 0 | EH2: 0 | EI2: 0
A3: 가공김(조미김 또는 구운김) | B3: 검사건수 | C3: 0 | D3: 0 | E3: 0 | F3: 0 | G3: 0 | H3: 0 | I3: 0 | J3: 0 | K3: 0 | L3: 0 | M3: 0 | N3: 0 | O3: 0 | P3: 0 | Q3: 0 | R3: 0 | S3: 0 | T3: 0 | U3: 0 | V3: 0 | W3: 0 | X3: 0 | Y3: 0 | Z3: 0 | AA3: 0 | AB3: 0 | AC3: 0 | AD3: 0 | AE3: 0 | AF3: 0 | AG3: 0 | AH3: 0 | AI3: 0 | AJ3: 0 | AK3: 0 | AL3: 0 | AM3: 0 | AN3: 0 | AO3: 0 | AP3: 0 | AQ3: 0 | AR3: 0 | AS3: 0 | AT3: 0 | AU3: 0 | AV3: 0 | AW3: 0 | AX3: 0 | AY3: 0 | AZ3: 0 | BA3: 0 | BB3: 0 | BC3: 0 | BD3: 0 | BE3: 0 | BF3: 0 | BG3: 0 | BH3: 0 | BI3: 0 | BJ3: 0 | BK3: 0 | BL3: 0 | BM3: 0 | BN3: 0 | BO3: 0 | BP3: 0 | BQ3: 0 | BR3: 0 | BS3: 0 | BT3: 0 | BU3: 0 | BV3: 0 | BW3: 0 | BX3: 0 | BY3: 0 | BZ3: 0 | CA3: 0 | CB3: 0 | CC3: 0 | CD3: 0 | CE3: 0 | CF3: 0 | CG3: 0 | CH3: 0 | CI3: 0 | CJ3: 0 | CK3: 0 | CL3: 0 | CM3: 0 | CN3: 0 | CO3: 0 | CP3: 0 | CQ3: 0 | CR3: 0 | CS3: 0 | CT3: 0 | CU3: 0 | CV3: 0 | CW3: 0 | CX3: 0 | CY3: 0 | CZ3: 0 | DA3: 0 | DB3: 0 | DC3: 0 | DD3: 0 | DE3: 0 | DF3: 0 | DG3: 0 | DH3: 0 | DI3: 0 | DJ3: 0 | DK3: 0 | DL3: 0 | DM3: 0 | DN3: 0 | DO3: 0 | DP3: 0 | DQ3: 0 | DR3: 0 | DS3: 0 | DT3: 0 | DU3: 0 | DV3: 1 | DW3: 2 | DX3: 6 | DY3: 2 | DZ3: 1 | EA3: 1 | EB3: 3 | EC3: 5 | ED3: 1 | EE3: 3 | EF3: 4 | EG3: 4 | EH3: 21 | EI3: 9
A4: 가공두부 | B4: 검사건수 | C4: 0 | D4: 0 | E4: 0 | F4: 0 | G4: 0 | H4: 0 | I4: 0 | J4: 0 | K4: 0 | L4: 0 | M4: 0 | N4: 2 | O4: 2 | P4: 0 | Q4: 1 | R4: 1 | S4: 1 | T4: 1 | U4: 1 | V4: 2 | W4: 1 | X4: 1 | Y4: 2 | Z4: 1 | AA4: 1 | AB4: 2 | AC4: 1 | AD4: 1 | AE4: 2 | AF4: 6 | AG4: 1 | AH4: 2 | AI4: 1 | AJ4: 1 | AK4: 1 | AL4: 1 | AM4: 1 | AN4: 3 | AO4: 1 | AP4: 1 | AQ4: 3 | AR4: 3 | AS4: 2 | AT4: 4 | AU4: 1 | AV4: 1 | AW4: 3 | AX4: 1 | AY4: 2 | AZ4: 2 | BA4: 1 | BB4: 1 | BC4: 2 | BD4: 1 | BE4: 1 | BF4: 2 | BG4: 1 | BH4: 1 | BI4: 1 | BJ4: 2 | BK4: 1 | BL4: 1 | BM4: 3 | BN4: 1 | BO4: 1 | BP4: 1 | BQ4: 1 | BR4: 1 | BS4: 2 | BT4: 0 | BU4: 1 | BV4: 1 | BW4: 0 | BX4: 0 | BY4: 0 | BZ4: 0 | CA4: 0 | CB4: 0 | CC4: 0 | CD4: 0 | CE4: 0 | CF4: 0 | CG4: 0 | CH4: 0 | CI4: 0 | CJ4: 0 | CK4: 0 | CL4: 0 | CM4: 0 | CN4: 0 | CO4: 0 | CP4: 0 | CQ4: 0 | CR4: 0 | CS4: 0 | CT4: 0 | CU4: 1 | CV4: 0 | CW4: 0 | CX4: 0 | CY4: 0 | CZ4: 0 | DA4: 0 | DB4: 0 | DC4: 0 | DD4: 0 | DE4: 1 | DF4: 0 | DG4: 0 | DH4: 1 | DI4: 0 | DJ4: 0 | DK4: 0 | DL4: 0 | DM4: 0 | DN4: 0 | DO4: 0 | DP4: 0 | DQ4: 0 | DR4: 2 | DS4: 2 | DT4: 0 | DU4: 0 | DV4: 1 | DW4: 0 | DX4: 0 | DY4: 0 | DZ4: 4 | EA4: 0 | EB4: 0 | EC4: 0 | ED4: 0 | EE4: 2 | EF4: 0 | EG4: 0 | EH4: 0 | EI4: 0
A5: 가공유류 | B5: 검사건수 | C5: 0 | D5: 0 | E5: 0 | F5: 0 | G5: 0 | H5: 0 | I5: 0 | J5: 0 | K5: 0 | L5: 0 | M5: 0 | N5: 0 | O5: 1 | P5: 4 | Q5: 12 | R5: 68 | S5: 22 | T5: 19 | U5: 24 | V5: 23 | W5: 23 | X5: 25 | Y5: 36 | Z5: 56 | AA5: 59 | AB5: 51 | AC5: 70 | AD5: 53 | AE5: 78 | AF5: 67 | AG5: 57 | AH5: 80 | AI5: 59 | AJ5: 30 | AK5: 37 | AL5: 30 | AM5: 43 | AN5: 46 | AO5: 48 | AP5: 41 | AQ5: 51 | AR5: 77 | AS5: 69 | AT5: 67 | AU5: 47 | AV5: 44 | AW5: 41 | AX5: 45 | AY5: 71 | AZ5: 58 | BA5: 58 | BB5: 64 | BC5: 70 | BD5: 62 | BE5: 68 | BF5: 68 | BG5: 69 | BH5: 68 | BI5: 63 | BJ5: 82 | BK5: 101 | BL5: 86 | BM5: 113 | BN5: 113 | BO5: 77 | BP5: 96 | BQ5: 69 | BR5: 101 | BS5: 81 | BT5: 74 | BU5: 78 | BV5: 72 | BW5: 64 | BX5: 88 | BY5: 82 | BZ5: 96 | CA5: 83 | CB5: 82 | CC5: 65 | CD5: 112 | CE5: 80 | CF5: 81 | CG5: 75 | CH5: 63 | CI5: 83 | CJ5: 73 | CK5: 70 | CL5: 80 | CM5: 133 | CN5: 68 | CO5: 87 | CP5: 115 | CQ5: 85 | CR5: 61 | CS5: 54 | CT5: 75 | CU5: 78 | CV5: 77 | CW5: 77 | CX5: 88 | CY5: 98 | CZ5: 81 | DA5: 88 | DB5: 78 | DC5: 100 | DD5: 65 | DE5: 65 | DF5: 61 | DG5: 81 | DH5: 89 | DI5: 81 | DJ5: 75 | DK5: 71 | DL5: 105 | DM5: 59 | DN5: 61 | DO5: 89 | DP5: 65 | DQ5: 67 | DR5: 63 | DS5: 72 | DT5: 81 | DU5: 84 | DV5: 80 | DW5: 85 | DX5: 92 | DY5: 80 | DZ5: 59 | EA5: 81 | EB5: 70 | EC5: 59 | ED5: 63 | EE5: 72 | EF5: 88 | EG5: 111 | EH5: 69 | EI5: 36
A6: 가금류 | B6: 검사건수 | C6: 0 | D6: 0 | E6: 0 | F6: 0 | G6: 0 | H6: 0 | I6: 0 | J6: 0 | K6: 0 | L6: 0 | M6: 0 | N6: 0 | O6: 0 | P6: 0 | Q6: 0 | R6: 0 | S6: 0 | T6: 0 | U6: 0 | V6: 0 | W6: 0 | X6: 0 | Y6: 0 | Z6: 0 | AA6: 2 | AB6: 0 | AC6: 0 | AD6: 0 | AE6: 1 | AF6: 0 | AG6: 0 | AH6: 0 | AI6: 0 | AJ6: 0 | AK6: 0 | AL6: 0 | AM6: 0 | AN6: 0 | AO6: 0 | AP6: 0 | AQ6: 0 | AR6: 0 | AS6: 0 | AT6: 0 | AU6: 0 | AV6: 0 | AW6: 0 | AX6: 0 | AY6: 0 | AZ6: 0 | BA6: 0 | BB6: 0 | BC6: 0 | BD6: 0 | BE6: 0 | BF6: 2 | BG6: 0 | BH6: 0 | BI6: 0 | BJ6: 0 | BK6: 0 | BL6: 0 | BM6: 1 | BN6: 0 | BO6: 0 | BP6: 2 | BQ6: 2 | BR6: 2 | BS6: 0 | BT6: 0 | BU6: 0 | BV6: 2 | BW6: 2 | BX6: 0 | BY6: 0 | BZ6: 0 | CA6: 0 | CB6: 3 | CC6: 2 | CD6: 5 | CE6: 3 | CF6: 0 | CG6: 0 | CH6: 3 | CI6: 1 | CJ6: 0 | CK6: 0 | CL6: 0 | CM6: 0 | CN6: 0 | CO6: 0 | CP6: 0 | CQ6: 0 | CR6: 0 | CS6: 0 | CT6: 0 | CU6: 3 | CV6: 0 | CW6: 0 | CX6: 0 | CY6: 2 | CZ6: 0 | DA6: 0 | DB6: 0 | DC6: 2 | DD6: 0 | DE6: 3 | DF6: 0 | DG6: 0 | DH6: 3 | DI6: 0 | DJ6: 4 | DK6: 0 | DL6: 0 | DM6: 0 | DN6: 0 | DO6: 4 | DP6: 2 | DQ6: 1 | DR6: 0 | DS6: 0 | DT6: 1 | DU6: 0 | DV6: 3 | DW6: 0 | DX6: 0 | DY6: 2 | DZ6: 1 | EA6: 2 | EB6: 0 | EC6: 1 | ED6: 0 | EE6: 1 | EF6: 3 | EG6: 0 | EH6: 3 | EI6: 0
A7: 가르시니아캄보지아 추출물 | B7: 검사건수 | C7: 0 | D7: 0 | E7: 0 | F7: 0 | G7: 0 | H7: 0 | I7: 0 | J7: 0 | K7: 0 | L7: 0 | M7: 0 | N7: 0 | O7: 0 | P7: 0 | Q7: 0 | R7: 0 | S7: 0 | T7: 0 | U7: 0 | V7: 0 | W7: 0 | X7: 0 | Y7: 0 | Z7: 0 | AA7: 0 | AB7: 0 | AC7: 0 | AD7: 0 | AE7: 0 | AF7: 1 | AG7: 0 | AH7: 0 | AI7: 0 | AJ7: 0 | AK7: 0 | AL7: 0 | AM7: 0 | AN7: 0 | AO7: 0 | AP7: 0 | AQ7: 0 | AR7: 0 | AS7: 0 | AT7: 0 | AU7: 0 | AV7: 0 | AW7: 0 | AX7: 0 | AY7: 0 | AZ7: 0 | BA7: 4 | BB7: 0 | BC7: 0 | BD7: 0 | BE7: 0 | BF7: 2 | BG7: 0 | BH7: 0 | BI7: 0 | BJ7: 0 | BK7: 0 | BL7: 0 | BM7: 0 | BN7: 0 | BO7: 0 | BP7: 0 | BQ7: 0 | BR7: 0 | BS7: 0 | BT7: 0 | BU7: 0 | BV7: 0 | BW7: 0 | BX7: 0 | BY7: 0 | BZ7: 0 | CA7: 0 | CB7: 0 | CC7: 0 | CD7: 0 | CE7: 0 | CF7: 0 | CG7: 0 | CH7: 0 | CI7: 0 | CJ7: 0 | CK7: 0 | CL7: 0 | CM7: 0 | CN7: 0 | CO7: 0 | CP7: 0 | CQ7: 0 | CR7: 0 | CS7: 0 | CT7: 1 | CU7: 0 | CV7: 0 | CW7: 0 | CX7: 0 | CY7: 0 | CZ7: 0 | DA7: 0 | DB7: 0 | DC7: 0 | DD7: 0 | DE7: 0 | DF7: 0 | DG7: 0 | DH7: 0 | DI7: 0 | DJ7: 0 | DK7: 0 | DL7: 0 | DM7: 0 | DN7: 0 | DO7: 0 | DP7: 0 | DQ7: 0 | DR7: 0 | DS7: 0 | DT7: 0 | DU7: 0 | DV7: 0 | DW7: 0 | DX7: 0 | DY7: 0 | DZ7: 0 | EA7: 0 | EB7: 0 | EC7: 0 | ED7: 0 | EE7: 0 | EF7: 0 | EG7: 0 | EH7: 0 | EI7: 0
A8: 감귤류 | B8: 검사건수 | C8: 0 | D8: 0 | E8: 0 | F8: 0 | G8: 0 | H8: 0 | I8: 0 | J8: 0 | K8: 0 | L8: 0 | M8: 0 | N8: 0 | O8: 0 | P8: 0 | Q8: 0 | R8: 0 | S8: 0 | T8: 0 | U8: 0 | V8: 0 | W8: 0 | X8: 0 | Y8: 0 | Z8: 0 | AA8: 0 | AB8: 0 | AC8: 0 | AD8: 0 | AE8: 0 | AF8: 0 | AG8: 0 | AH8: 0 | AI8: 1 | AJ8: 0 | AK8: 0 | AL8: 0 | AM8: 0 | AN8: 0 | AO8: 0 | AP8: 0 | AQ8: 0 | AR8: 0 | AS8: 0 | AT8: 0 | AU8: 0 | AV8: 0 | AW8: 0 | AX8: 1 | AY8: 3 | AZ8: 1 | BA8: 6 | BB8: 1 | BC8: 0 | BD8: 0 | BE8: 0 | BF8: 0 | BG8: 0 | BH8: 0 | BI8: 1 | BJ8: 0 | BK8: 0 | BL8: 0 | BM8: 0 | BN8: 0 | BO8: 0 | BP8: 0 | BQ8: 0 | BR8: 0 | BS8: 0 | BT8: 0 | BU8: 0 | BV8: 0 | BW8: 0 | BX8: 0 | BY8: 0 | BZ8: 0 | CA8: 0 | CB8: 0 | CC8: 0 | CD8: 0 | CE8: 0 | CF8: 0 | CG8: 0 | CH8: 0 | CI8: 0 | CJ8: 0 | CK8: 0 | CL8: 0 | CM8: 0 | CN8: 0 | CO8: 0 | CP8: 0 | CQ8: 0 | CR8: 0 | CS8: 0 | CT8: 0 | CU8: 0 | CV8: 0 | CW8: 0 | CX8: 0 | CY8: 0 | CZ8: 0 | DA8: 0 | DB8: 0 | DC8: 0 | DD8: 0 | DE8: 0 | DF8: 0 | DG8: 0 | DH8: 0 | DI8: 0 | DJ8: 0 | DK8: 2 | DL8: 0 | DM8: 0 | DN8: 0 | DO8: 0 | DP8: 0 | DQ8: 0 | DR8: 0 | DS8: 0 | DT8: 0 | DU8: 0 | DV8: 0 | DW8: 0 | DX8: 0 | DY8: 0 | DZ8: 0 | EA8: 0 | EB8: 0 | EC8: 0 | ED8: 0 | EE8: 0 | EF8: 0 | EG8: 0 | EH8: 0 | EI8: 0
A9: 감자 | B9: 검사건수 | C9: 0 | D9: 0 | E9: 0 | F9: 0 | G9: 0 | H9: 0 | I9: 0 | J9: 0 | K9: 0 | L9: 0 | M9: 0 | N9: 0 | O9: 0 | P9: 0 | Q9: 0 | R9: 0 | S9: 0 | T9: 0 | U9: 0 | V9: 0 | W9: 0 | X9: 0 | Y9: 0 | Z9: 0 | AA9: 0 | AB9: 0 | AC9: 0 | AD9: 0 | AE9: 0 | AF9: 0 | AG9: 0 | AH9: 0 | AI9: 0 | AJ9: 0 | AK9: 0 | AL9: 0 | AM9: 0 | AN9: 0 | AO9: 0 | AP9: 0 | AQ9: 0 | AR9: 0 | AS9: 0 | AT9: 0 | AU9: 0 | AV9: 0 | AW9: 0 | AX9: 0 | AY9: 1 | AZ9: 1 | BA9: 0 | BB9: 0 | BC9: 0 | BD9: 0 | BE9: 2 | BF9: 0 | BG9: 0 | BH9: 0 | BI9: 0 | BJ9: 0 | BK9: 0 | BL9: 0 | BM9: 0 | BN9: 0 | BO9: 0 | BP9: 0 | BQ9: 0 | BR9: 0 | BS9: 0 | BT9: 0 | BU9: 0 | BV9: 0 | BW9: 0 | BX9: 0 | BY9: 0 | BZ9: 0 | CA9: 0 | CB9: 0 | CC9: 0 | CD9: 0 | CE9: 0 | CF9: 0 | CG9: 0 | CH9: 0 | CI9: 0 | CJ9: 0 | CK9: 0 | CL9: 0 | CM9: 0 | CN9: 0 | CO9: 0 | CP9: 0 | CQ9: 0 | CR9: 0 | CS9: 0 | CT9: 0 | CU9: 0 | CV9: 0 | CW9: 0 | CX9: 0 | CY9: 0 | CZ9: 0 | DA9: 0 | DB9: 0 | DC9: 0 | DD9: 0 | DE9: 0 | DF9: 0 | DG9: 0 | DH9: 0 | DI9: 0 | DJ9: 0 | DK9: 0 | DL9: 0 | DM9: 0 | DN9: 0 | DO9: 0 | DP9: 0 | DQ9: 0 | DR9: 0 | DS9: 0 | DT9: 0 | DU9: 0 | DV9: 0 | DW9: 0 | DX9: 0 | DY9: 0 | DZ9: 0 | EA9: 0 | EB9: 0 | EC9: 0 | ED9: 0 | EE9: 0 | EF9: 0 | EG9: 0 | EH9: 0 | EI9: 0
A10: 갑각류 | B10: 검사건수 | C10: 0 | D10: 0 | E10: 0 | F10: 0 | G10: 0 | H10: 0 | I10: 0 | J10: 0 | K10: 0 | L10: 0 | M10: 0 | N10: 0 | O10: 0 | P10: 0 | Q10: 0 | R10: 0 | S10: 0 | T10: 0 | U10: 0 | V10: 0 | W10: 0 | X10: 0 | Y10: 0 | Z10: 0 | AA10: 0 | AB10: 0 | AC10: 0 | AD10: 0 | AE10: 0 | AF10: 0 | AG10: 0 | AH10: 0 | AI10: 0 | AJ10: 0 | AK10: 0 | AL10: 0 | AM10: 0 | AN10: 0 | AO10: 0 | AP10: 0 | AQ10: 0 | AR10: 0 | AS10: 0 | AT10: 0 | AU10: 0 | AV10: 0 | AW10: 0 | AX10: 0 | AY10: 0 | AZ10: 0 | BA10: 0 | BB10: 0 | BC10: 0 | BD10: 0 | BE10: 0 | BF10: 0 | BG10: 0 | BH10: 0 | BI10: 0 | BJ10: 0 | BK10: 0 | BL10: 0 | BM10: 0 | BN10: 0 | BO10: 0 | BP10: 0 | BQ10: 0 | BR10: 0 | BS10: 0 | BT10: 0 | BU10: 4 | BV10: 3 | BW10: 3 | BX10: 2 | BY10: 10 | BZ10: 6 | CA10: 0 | CB10: 0 | CC10: 2 | CD10: 1 | CE10: 1 | CF10: 3 | CG10: 5 | CH10: 9 | CI10: 5 | CJ10: 2 | CK10: 5 | CL10: 2 | CM10: 0 | CN10: 3 | CO10: 1 | CP10: 1 | CQ10: 1 | CR10: 0 | CS10: 5 | CT10: 6 | CU10: 3 | CV10: 1 | CW10: 6 | CX10: 0 | CY10: 1 | CZ10: 3 | DA10: 8 | DB10: 0 | DC10: 0 | DD10: 1 | DE10: 1 | DF10: 1 | DG10: 1 | DH10: 0 | DI10: 0 | DJ10: 0 | DK10: 0 | DL10: 0 | DM10: 0 | DN10: 1 | DO10: 0 | DP10: 0 | DQ10: 2 | DR10: 2 | DS10: 3 | DT10: 3 | DU10: 2 | DV10: 0 | DW10: 1 | DX10: 0 | DY10: 0 | DZ10: 0 | EA10: 0 | EB10: 0 | EC10: 0 | ED10: 0 | EE10: 2 | EF10: 3 | EG10: 0 | EH10: 0 | EI10: 0
A11: 개별인정원료 | B11: 검사건수 | C11: 0 | D11: 0 | E11: 0 | F11: 0 | G11: 0 | H11: 0 | I11: 0 | J11: 0 | K11: 0 | L11: 0 | M11: 0 | N11: 0 | O11: 0 | P11: 0 | Q11: 0 | R11: 0 | S11: 0 | T11: 0 | U11: 0 | V11: 0 | W11: 0 | X11: 0 | Y11: 0 | Z11: 0 | AA11: 0 | AB11: 0 | AC11: 0 | AD11: 0 | AE11: 0 | AF11: 0 | AG11: 0 | AH11: 0 | AI11: 0 | AJ11: 0 | AK11: 0 | AL11: 0 | AM11: 0 | AN11: 0 | AO11: 0 | AP11: 0 | AQ11: 0 | AR11: 0 | AS11: 0 | AT11: 0 | AU11: 0 | AV11: 0 | AW11: 0 | AX11: 0 | AY11: 0 | AZ11: 0 | BA11: 0 | BB11: 0 | BC11: 0 | BD11: 0 | BE11: 0 | BF11: 0 | BG11: 0 | BH11: 0 | BI11: 0 | BJ11: 0 | BK11: 0 | BL11: 0 | BM11: 0 | BN11: 0 | BO11: 0 | BP11: 0 | BQ11: 0 | BR11: 0 | BS11: 0 | BT11: 0 | BU11: 0 | BV11: 0 | BW11: 0 | BX11: 1 | BY11: 0 | BZ11: 0 | CA11: 0 | CB11: 0 | CC11: 0 | CD11: 0 | CE11: 0 | CF11: 0 | CG11: 0 | CH11: 0 | CI11: 0 | CJ11: 0 | CK11: 0 | CL11: 0 | CM11: 0 | CN11: 0 | CO11: 0 | CP11: 0 | CQ11: 0 | CR11: 0 | CS11: 0 | CT11: 0 | CU11: 0 | CV11: 0 | CW11: 0 | CX11: 0 | CY11: 0 | CZ11: 0 | DA11: 0 | DB11: 0 | DC11: 0 | DD11: 0 | DE11: 0 | DF11: 0 | DG11: 0 | DH11: 0 | DI11: 0 | DJ11: 0 | DK11: 0 | DL11: 0 | DM11: 0 | DN11: 0 | DO11: 0 | DP11: 0 | DQ11: 0 | DR11: 0 | DS11: 0 | DT11: 0 | DU11: 0 | DV11: 0 | DW11: 0 | DX11: 0 | DY11: 0 | DZ11: 0 | EA11: 0 | EB11: 0 | EC11: 0 | ED11: 0 | EE11: 0 | EF11: 0 | EG11: 0 | EH11: 0 | EI11: 0
A12: 건면 | B12: 검사건수 | C12: 0 | D12: 0 | E12: 0 | F12: 0 | G12: 0 | H12: 0 | I12: 0 | J12: 0 | K12: 0 | L12: 0 | M12: 0 | N12: 0 | O12: 0 | P12: 0 | Q12: 0 | R12: 0 | S12: 0 | T12: 0 | U12: 0 | V12: 0 | W12: 0 | X12: 0 | Y12: 0 | Z12: 0 | AA12: 0 | AB12: 0 | AC12: 0 | AD12: 0 | AE12: 0 | AF12: 0 | AG12: 1 | AH12: 1 | AI12: 3 | AJ12: 1 | AK12: 2 | AL12: 5 | AM12: 1 | AN12: 2 | AO12: 0 | AP12: 0 | AQ12: 0 | AR12: 0 | AS12: 0 | AT12: 2 | AU12: 1 | AV12: 0 | AW12: 0 | AX12: 0 | AY12: 1 | AZ12: 0 | BA12: 2 | BB12: 0 | BC12: 0 | BD12: 0 | BE12: 0 | BF12: 0 | BG12: 2 | BH12: 0 | BI12: 0 | BJ12: 0 | BK12: 2 | BL12: 1 | BM12: 0 | BN12: 1 | BO12: 0 | BP12: 3 | BQ12: 3 | BR12: 1 | BS12: 0 | BT12: 0 | BU12: 0 | BV12: 3 | BW12: 4 | BX12: 2 | BY12: 0 | BZ12: 0 | CA12: 0 | CB12: 0 | CC12: 0 | CD12: 1 | CE12: 2 | CF12: 0 | CG12: 0 | CH12: 0 | CI12: 0 | CJ12: 3 | CK12: 0 | CL12: 0 | CM12: 0 | CN12: 1 | CO12: 0 | CP12: 0 | CQ12: 0 | CR12: 0 | CS12: 0 | CT12: 0 | CU12: 1 | CV12: 0 | CW12: 2 | CX12: 0 | CY12: 1 | CZ12: 0 | DA12: 0 | DB12: 0 | DC12: 0 | DD12: 0 | DE12: 0 | DF12: 0 | DG12: 1 | DH12: 2 | DI12: 0 | DJ12: 2 | DK12: 0 | DL12: 0 | DM12: 0 | DN12: 0 | DO12: 0 | DP12: 0 | DQ12: 0 | DR12: 0 | DS12: 2 | DT12: 4 | DU12: 0 | DV12: 0 | DW12: 0 | DX12: 0 | DY12: 0 | DZ12: 0 | EA12: 0 | EB12: 0 | EC12: 1 | ED12: 0 | EE12: 1 | EF12: 2 | EG12: 0 | EH12: 0 | EI12: 0
A13: 건조저장육류 | B13: 검사건수 | C13: 0 | D13: 0 | E13: 0 | F13: 0 | G13: 0 | H13: 0 | I13: 0 | J13: 0 | K13: 0 | L13: 1 | M13: 1 | N13: 2 | O13: 4 | P13: 3 | Q13: 9 | R13: 8 | S13: 7 | T13: 10 | U13: 10 | V13: 12 | W13: 6 | X13: 15 | Y13: 27 | Z13: 69 | AA13: 57 | AB13: 51 | AC13: 45 | AD13: 47 | AE13: 58 | AF13: 56 | AG13: 46 | AH13: 80 | AI13: 69 | AJ13: 40 | AK13: 40 | AL13: 61 | AM13: 49 | AN13: 40 | AO13: 58 | AP13: 61 | AQ13: 80 | AR13: 66 | AS13: 43 | AT13: 43 | AU13: 42 | AV13: 40 | AW13: 38 | AX13: 51 | AY13: 67 | AZ13: 56 | BA13: 57 | BB13: 64 | BC13: 60 | BD13: 47 | BE13: 53 | BF13: 61 | BG13: 60 | BH13: 72 | BI13: 59 | BJ13: 48 | BK13: 48 | BL13: 52 | BM13: 51 | BN13: 73 | BO13: 71 | BP13: 70 | BQ13: 54 | BR13: 63 | BS13: 58 | BT13: 47 | BU13: 52 | BV13: 51 | BW13: 60 | BX13: 88 | BY13: 56 | BZ13: 83 | CA13: 68 | CB13: 57 | CC13: 49 | CD13: 56 | CE13: 58 | CF13: 66 | CG13: 59 | CH13: 60 | CI13: 54 | CJ13: 106 | CK13: 51 | CL13: 78 | CM13: 62 | CN13: 60 | CO13: 54 | CP13: 77 | CQ13: 64 | CR13: 57 | CS13: 41 | CT13: 57 | CU13: 62 | CV13: 98 | CW13: 56 | CX13: 79 | CY13: 52 | CZ13: 43 | DA13: 62 | DB13: 53 | DC13: 54 | DD13: 62 | DE13: 51 | DF13: 46 | DG13: 68 | DH13: 47 | DI13: 55 | DJ13: 54 | DK13: 67 | DL13: 53 | DM13: 57 | DN13: 70 | DO13: 63 | DP13: 53 | DQ13: 62 | DR13: 59 | DS13: 57 | DT13: 61 | DU13: 59 | DV13: 65 | DW13: 55 | DX13: 47 | DY13: 58 | DZ13: 38 | EA13: 57 | EB13: 60 | EC13: 41 | ED13: 69 | EE13: 51 | EF13: 52 | EG13: 55 | EH13: 59 | EI13: 32
... A218: 효소처리스테비아 | B218: 검사건수 | C218: 0 | D218: 0 | E218: 0 | F218: 0 | G218: 0 | H218: 0 | I218: 0 | J218: 0 | K218: 0 | L218: 0 | M218: 0 | N218: 0 | O218: 0 | P218: 0 | Q218: 0 | R218: 0 | S218: 0 | T218: 0 | U218: 0 | V218: 0 | W218: 0 | X218: 0 | Y218: 0 | Z218: 0 | AA218: 0 | AB218: 1 | AC218: 0 | AD218: 0 | AE218: 1 | AF218: 0 | AG218: 0 | AH218: 0 | AI218: 2 | AJ218: 0 | AK218: 0 | AL218: 1 | AM218: 0 | AN218: 0 | AO218: 1 | AP218: 0 | AQ218: 1 | AR218: 1 | AS218: 0 | AT218: 0 | AU218: 2 | AV218: 0 | AW218: 0 | AX218: 1 | AY218: 0 | AZ218: 0 | BA218: 1 | BB218: 0 | BC218: 0 | BD218: 1 | BE218: 0 | BF218: 0 | BG218: 1 | BH218: 0 | BI218: 0 | BJ218: 1 | BK218: 0 | BL218: 0 | BM218: 1 | BN218: 0 | BO218: 0 | BP218: 1 | BQ218: 0 | BR218: 0 | BS218: 1 | BT218: 0 | BU218: 0 | BV218: 1 | BW218: 0 | BX218: 0 | BY218: 1 | BZ218: 0 | CA218: 0 | CB218: 0 | CC218: 1 | CD218: 0 | CE218: 0 | CF218: 1 | CG218: 0 | CH218: 0 | CI218: 1 | CJ218: 0 | CK218: 1 | CL218: 1 | CM218: 0 | CN218: 0 | CO218: 1 | CP218: 0 | CQ218: 0 | CR218: 1 | CS218: 0 | CT218: 0 | CU218: 1 | CV218: 0 | CW218: 0 | CX218: 1 | CY218: 0 | CZ218: 0 | DA218: 1 | DB218: 0 | DC218: 0 | DD218: 1 | DE218: 0 | DF218: 0 | DG218: 1 | DH218: 0 | DI218: 0 | DJ218: 1 | DK218: 0 | DL218: 0 | DM218: 1 | DN218: 0 | DO218: 0 | DP218: 1 | DQ218: 0 | DR218: 0 | DS218: 0 | DT218: 0 | DU218: 0 | DV218: 0 | DW218: 0 | DX218: 0 | DY218: 0 | DZ218: 0 | EA218: 0 | EB218: 0 | EC218: 0 | ED218: 0 | EE218: 0 | EF218: 0 | EG218: 0 | EH218: 0 | EI218: 0

Sheet 검출건수
A1: 품목 | B1: 구분 | C1: 2015-04-07~2015-05-06 | D1: 2015-05-07~2015-06-05 | E1: 2015-06-06~2015-07-05 | F1: 2015-07-06~2015-08-04 | G1: 2015-08-05~2015-09-03 | H1: 2015-09-04~2015-10-03 | I1: 2015-10-04~2015-11-02 | J1: 2015-11-03~2015-12-02 | K1: 2015-12-03~2016-01-01 | L1: 2016-01-02~2016-01-31 | M1: 2016-02-01~2016-03-01 | N1: 2016-03-02~2016-03-31 | O1: 2016-04-01~2016-04-30 | P1: 2016-05-01~2016-05-30 | Q1: 2016-05-31~2016-06-29 | R1: 2016-06-30~2016-07-29 | S1: 2016-07-30~2016-08-28 | T1: 2016-08-29~2016-09-27 | U1: 2016-09-28~2016-10-27 | V1: 2016-10-28~2016-11-26 | W1: 2016-11-27~2016-12-26 | X1: 2016-12-27~2017-01-25 | Y1: 2017-01-26~2017-02-24 | Z1: 2017-02-25~2017-03-26 | AA1: 2017-03-27~2017-04-25 | AB1: 2017-04-26~2017-05-25 | AC1: 2017-05-26~2017-06-24 | AD1: 2017-06-25~2017-07-24 | AE1: 2017-07-25~2017-08-23 | AF1: 2017-08-24~2017-09-22 | AG1: 2017-09-23~2017-10-22 | AH1: 2017-10-23~2017-11-21 | AI1: 2017-11-22~2017-12-21 | AJ1: 2017-12-22~2018-01-20 | AK1: 2018-01-21~2018-02-19 | AL1: 2018-02-20~2018-03-21 | AM1: 2018-03-22~2018-04-20 | AN1: 2018-04-21~2018-05-20 | AO1: 2018-05-21~2018-06-19 | AP1: 2018-06-20~2018-07-19 | AQ1: 2018-07-20~2018-08-18 | AR1: 2018-08-19~2018-09-17 | AS1: 2018-09-18~2018-10-17 | AT1: 2018-10-18~2018-11-16 | AU1: 2018-11-17~2018-12-16 | AV1: 2018-12-17~2019-01-15 | AW1: 2019-01-16~2019-02-14 | AX1: 2019-02-15~2019-03-16 | AY1: 2019-03-17~2019-04-15 | AZ1: 2019-04-16~2019-05-15 | BA1: 2019-05-16~2019-06-14 | BB1: 2019-06-15~2019-07-14 | BC1: 2019-07-15~2019-08-13 | BD1: 2019-08-14~2019-09-12 | BE1: 2019-09-13~2019-10-12 | BF1: 2019-10-13~2019-11-11 | BG1: 2019-11-12~2019-12-11 | BH1: 2019-12-12~2020-01-10 | BI1: 2020-01-11~2020-02-09 | BJ1: 2020-02-10~2020-03-10 | BK1: 2020-03-11~2020-04-09 | BL1: 2020-04-10~2020-05-09 | BM1: 2020-05-10~2020-06-08 | BN1: 2020-06-09~2020-07-08 | BO1: 2020-07-09~2020-08-07 | BP1: 2020-08-08~2020-09-06 | BQ1: 2020-09-07~2020-10-06 | BR1: 2020-10-07~2020-11-05 | BS1: 2020-11-06~2020-12-05 | BT1: 2020-12-06~2021-01-04 | BU1: 2021-01-05~2021-02-03 | BV1: 2021-02-04~2021-03-05 | BW1: 2021-03-06~2021-04-04 | BX1: 2021-04-05~2021-05-04 | BY1: 2021-05-05~2021-06-03 | BZ1: 2021-06-04~2021-07-03 | CA1: 2021-07-04~2021-08-02 | CB1: 2021-08-03~2021-09-01 | CC1: 2021-09-02~2021-10-01 | CD1: 2021-10-02~2021-10-31 | CE1: 2021-11-01~2021-11-30 | CF1: 2021-12-01~2021-12-30 | CG1: 2021-12-31~2022-01-29 | CH1: 2022-01-30~2022-02-28 | CI1: 2022-03-01~2022-03-30 | CJ1: 2022-03-31~2022-04-29 | CK1: 2022-04-30~2022-05-29 | CL1: 2022-05-30~2022-06-28 | CM1: 2022-06-29~2022-07-28 | CN1: 2022-07-29~2022-08-27 | CO1: 2022-08-28~2022-09-26 | CP1: 2022-09-27~2022-10-26 | CQ1: 2022-10-27~2022-11-25 | CR1: 2022-11-26~2022-12-25 | CS1: 2022-12-26~2023-01-24 | CT1: 2023-01-25~2023-02-23 | CU1: 2023-02-24~2023-03-25 | CV1: 2023-03-26~2023-04-24 | CW1: 2023-04-25~2023-05-24 | CX1: 2023-05-25~2023-06-23 | CY1: 2023-06-24~2023-07-23 | CZ1: 2023-07-24~2023-08-22 | DA1: 2023-08-23~2023-09-21 | DB1: 2023-09-22~2023-10-21 | DC1: 2023-10-22~2023-11-20 | DD1: 2023-11-21~2023-12-20 | DE1: 2023-12-21~2024-01-19 | DF1: 2024-01-20~2024-02-18 | DG1: 2024-02-19~2024-03-19 | DH1: 2024-03-20~2024-04-18 | DI1: 2024-04-19~2024-05-18 | DJ1: 2024-05-19~2024-06-17 | DK1: 2024-06-18~2024-07-17 | DL1: 2024-07-18~2024-08-16 | DM1: 2024-08-17~2024-09-15 | DN1: 2024-09-16~2024-10-15 | DO1: 2024-10-16~2024-11-14 | DP1: 2024-11-15~2024-12-14 | DQ1: 2024-12-15~2025-01-13 | DR1: 2025-01-14~2025-02-12 | DS1: 2025-02-13~2025-03-14 | DT1: 2025-03-15~2025-04-13 | DU1: 2025-04-14~2025-05-13 | DV1: 2025-05-14~2025-06-12 | DW1: 2025-06-13~2025-07-12 | DX1: 2025-07-13~2025-08-11 | DY1: 2025-08-12~2025-09-10 | DZ1: 2025-09-11~2025-10-10 | EA1: 2025-10-11~2025-11-09 | EB1: 2025-11-10~2025-12-09 | EC1: 2025-12-10~2026-01-08 | ED1: 2026-01-09~2026-02-07 | EE1: 2026-02-08~2026-03-09 | EF1: 2026-03-10~2026-04-08 | EG1: 2026-04-09~2026-05-08 | EH1: 2026-05-09~2026-06-07 | EI1: 2026-06-08~2026-07-07
A2: NAG(엔에이지, N-아세틸글루코사민, N-Acetylglucosamine) | B2: 검출건수 | C2: 0 | D2: 0 | E2: 0 | F2: 0 | G2: 0 | H2: 0 | I2: 0 | J2: 0 | K2: 0 | L2: 0 | M2: 0 | N2: 0 | O2: 0 | P2: 0 | Q2: 0 | R2: 0 | S2: 0 | T2: 0 | U2: 0 | V2: 0 | W2: 0 | X2: 0 | Y2: 0 | Z2: 0 | AA2: 0 | AB2: 0 | AC2: 0 | AD2: 0 | AE2: 0 | AF2: 0 | AG2: 0 | AH2: 0 | AI2: 0 | AJ2: 0 | AK2: 0 | AL2: 0 | AM2: 0 | AN2: 0 | AO2: 0 | AP2: 0 | AQ2: 0 | AR2: 0 | AS2: 0 | AT2: 0 | AU2: 0 | AV2: 0 | AW2: 0 | AX2: 0 | AY2: 0 | AZ2: 0 | BA2: 0 | BB2: 0 | BC2: 0 | BD2: 0 | BE2: 0 | BF2: 0 | BG2: 0 | BH2: 0 | BI2: 0 | BJ2: 0 | BK2: 0 | BL2: 0 | BM2: 0 | BN2: 0 | BO2: 0 | BP2: 0 | BQ2: 0 | BR2: 0 | BS2: 0 | BT2: 0 | BU2: 0 | BV2: 0 | BW2: 0 | BX2: 0 | BY2: 0 | BZ2: 0 | CA2: 0 | CB2: 0 | CC2: 0 | CD2: 0 | CE2: 0 | CF2: 0 | CG2: 0 | CH2: 0 | CI2: 0 | CJ2: 0 | CK2: 0 | CL2: 0 | CM2: 0 | CN2: 0 | CO2: 0 | CP2: 0 | CQ2: 0 | CR2: 0 | CS2: 0 | CT2: 0 | CU2: 0 | CV2: 0 | CW2: 0 | CX2: 0 | CY2: 0 | CZ2: 0 | DA2: 0 | DB2: 0 | DC2: 0 | DD2: 0 | DE2: 0 | DF2: 0 | DG2: 0 | DH2: 0 | DI2: 0 | DJ2: 0 | DK2: 0 | DL2: 0 | DM2: 0 | DN2: 0 | DO2: 0 | DP2: 0 | DQ2: 0 | DR2: 0 | DS2: 0 | DT2: 0 | DU2: 0 | DV2: 0 | DW2: 0 | DX2: 0 | DY2: 0 | DZ2: 0 | EA2: 0 | EB2: 0 | EC2: 0 | ED2: 0 | EE2: 0 | EF2: 0 | EG2: 0 | EH2: 0 | EI2: 0
A3: 가공김(조미김 또는 구운김) | B3: 검출건수 | C3: 0 | D3: 0 | E3: 0 | F3: 0 | G3: 0 | H3: 0 | I3: 0 | J3: 0 | K3: 0 | L3: 0 | M3: 0 | N3: 0 | O3: 0 | P3: 0 | Q3: 0 | R3: 0 | S3: 0 | T3: 0 | U3: 0 | V3: 0 | W3: 0 | X3: 0 | Y3: 0 | Z3: 0 | AA3: 0 | AB3: 0 | AC3: 0 | AD3: 0 | AE3: 0 | AF3: 0 | AG3: 0 | AH3: 0 | AI3: 0 | AJ3: 0 | AK3: 0 | AL3: 0 | AM3: 0 | AN3: 0 | AO3: 0 | AP3: 0 | AQ3: 0 | AR3: 0 | AS3: 0 | AT3: 0 | AU3: 0 | AV3: 0 | AW3: 0 | AX3: 0 | AY3: 0 | AZ3: 0 | BA3: 0 | BB3: 0 | BC3: 0 | BD3: 0 | BE3: 0 | BF3: 0 | BG3: 0 | BH3: 0 | BI3: 0 | BJ3: 0 | BK3: 0 | BL3: 0 | BM3: 0 | BN3: 0 | BO3: 0 | BP3: 0 | BQ3: 0 | BR3: 0 | BS3: 0 | BT3: 0 | BU3: 0 | BV3: 0 | BW3: 0 | BX3: 0 | BY3: 0 | BZ3: 0 | CA3: 0 | CB3: 0 | CC3: 0 | CD3: 0 | CE3: 0 | CF3: 0 | CG3: 0 | CH3: 0 | CI3: 0 | CJ3: 0 | CK3: 0 | CL3: 0 | CM3: 0 | CN3: 0 | CO3: 0 | CP3: 0 | CQ3: 0 | CR3: 0 | CS3: 0 | CT3: 0 | CU3: 0 | CV3: 0 | CW3: 0 | CX3: 0 | CY3: 0 | CZ3: 0 | DA3: 0 | DB3: 0 | DC3: 0 | DD3: 0 | DE3: 0 | DF3: 0 | DG3: 0 | DH3: 0 | DI3: 0 | DJ3: 0 | DK3: 0 | DL3: 0 | DM3: 0 | DN3: 0 | DO3: 0 | DP3: 0 | DQ3: 0 | DR3: 0 | DS3: 0 | DT3: 0 | DU3: 0 | DV3: 0 | DW3: 0 | DX3: 0 | DY3: 0 | DZ3: 0 | EA3: 0 | EB3: 0 | EC3: 0 | ED3: 0 | EE3: 0 | EF3: 0 | EG3: 0 | EH3: 0 | EI3: 0
A4: 가공두부 | B4: 검출건수 | C4: 0 | D4: 0 | E4: 0 | F4: 0 | G4: 0 | H4: 0 | I4: 0 | J4: 0 | K4: 0 | L4: 0 | M4: 0 | N4: 0 | O4: 0 | P4: 0 | Q4: 0 | R4: 0 | S4: 0 | T4: 0 | U4: 0 | V4: 0 | W4: 0 | X4: 0 | Y4: 0 | Z4: 0 | AA4: 0 | AB4: 0 | AC4: 0 | AD4: 0 | AE4: 0 | AF4: 0 | AG4: 0 | AH4: 0 | AI4: 0 | AJ4: 0 | AK4: 0 | AL4: 0 | AM4: 0 | AN4: 0 | AO4: 0 | AP4: 0 | AQ4: 0 | AR4: 0 | AS4: 0 | AT4: 0 | AU4: 0 | AV4: 0 | AW4: 0 | AX4: 0 | AY4: 0 | AZ4: 0 | BA4: 0 | BB4: 0 | BC4: 0 | BD4: 0 | BE4: 0 | BF4: 0 | BG4: 0 | BH4: 0 | BI4: 0 | BJ4: 0 | BK4: 0 | BL4: 0 | BM4: 0 | BN4: 0 | BO4: 0 | BP4: 0 | BQ4: 0 | BR4: 0 | BS4: 0 | BT4: 0 | BU4: 0 | BV4: 0 | BW4: 0 | BX4: 0 | BY4: 0 | BZ4: 0 | CA4: 0 | CB4: 0 | CC4: 0 | CD4: 0 | CE4: 0 | CF4: 0 | CG4: 0 | CH4: 0 | CI4: 0 | CJ4: 0 | CK4: 0 | CL4: 0 | CM4: 0 | CN4: 0 | CO4: 0 | CP4: 0 | CQ4: 0 | CR4: 0 | CS4: 0 | CT4: 0 | CU4: 0 | CV4: 0 | CW4: 0 | CX4: 0 | CY4: 0 | CZ4: 0 | DA4: 0 | DB4: 0 | DC4: 0 | DD4: 0 | DE4: 0 | DF4: 0 | DG4: 0 | DH4: 0 | DI4: 0 | DJ4: 0 | DK4: 0 | DL4: 0 | DM4: 0 | DN4: 0 | DO4: 0 | DP4: 0 | DQ4: 0 | DR4: 0 | DS4: 0 | DT4: 0 | DU4: 0 | DV4: 0 | DW4: 0 | DX4: 0 | DY4: 0 | DZ4: 0 | EA4: 0 | EB4: 0 | EC4: 0 | ED4: 0 | EE4: 0 | EF4: 0 | EG4: 0 | EH4: 0 | EI4: 0
A5: 가공유류 | B5: 검출건수 | C5: 0 | D5: 0 | E5: 0 | F5: 0 | G5: 0 | H5: 0 | I5: 0 | J5: 0 | K5: 0 | L5: 0 | M5: 0 | N5: 0 | O5: 0 | P5: 0 | Q5: 0 | R5: 0 | S5: 0 | T5: 0 | U5: 0 | V5: 0 | W5: 0 | X5: 0 | Y5: 0 | Z5: 0 | AA5: 0 | AB5: 0 | AC5: 0 | AD5: 0 | AE5: 0 | AF5: 0 | AG5: 0 | AH5: 0 | AI5: 0 | AJ5: 0 | AK5: 0 | AL5: 0 | AM5: 0 | AN5: 0 | AO5: 0 | AP5: 0 | AQ5: 0 | AR5: 0 | AS5: 0 | AT5: 0 | AU5: 0 | AV5: 0 | AW5: 0 | AX5: 0 | AY5: 0 | AZ5: 0 | BA5: 0 | BB5: 0 | BC5: 0 | BD5: 0 | BE5: 0 | BF5: 0 | BG5: 0 | BH5: 0 | BI5: 0 | BJ5: 0 | BK5: 0 | BL5: 0 | BM5: 0 | BN5: 0 | BO5: 0 | BP5: 0 | BQ5: 0 | BR5: 0 | BS5: 0 | BT5: 0 | BU5: 0 | BV5: 0 | BW5: 0 | BX5: 0 | BY5: 0 | BZ5: 0 | CA5: 0 | CB5: 0 | CC5: 0 | CD5: 0 | CE5: 0 | CF5: 0 | CG5: 0 | CH5: 0 | CI5: 0 | CJ5: 0 | CK5: 0 | CL5: 0 | CM5: 0 | CN5: 0 | CO5: 0 | CP5: 0 | CQ5: 0 | CR5: 0 | CS5: 0 | CT5: 0 | CU5: 0 | CV5: 0 | CW5: 0 | CX5: 0 | CY5: 0 | CZ5: 0 | DA5: 0 | DB5: 0 | DC5: 0 | DD5: 0 | DE5: 0 | DF5: 0 | DG5: 0 | DH5: 0 | DI5: 0 | DJ5: 0 | DK5: 0 | DL5: 0 | DM5: 0 | DN5: 0 | DO5: 0 | DP5: 0 | DQ5: 0 | DR5: 0 | DS5: 0 | DT5: 0 | DU5: 0 | DV5: 0 | DW5: 0 | DX5: 0 | DY5: 0 | DZ5: 0 | EA5: 0 | EB5: 0 | EC5: 0 | ED5: 0 | EE5: 0 | EF5: 0 | EG5: 0 | EH5: 0 | EI5: 0
A6: 가금류 | B6: 검출건수 | C6: 0 | D6: 0 | E6: 0 | F6: 0 | G6: 0 | H6: 0 | I6: 0 | J6: 0 | K6: 0 | L6: 0 | M6: 0 | N6: 0 | O6: 0 | P6: 0 | Q6: 0 | R6: 0 | S6: 0 | T6: 0 | U6: 0 | V6: 0 | W6: 0 | X6: 0 | Y6: 0 | Z6: 0 | AA6: 0 | AB6: 0 | AC6: 0 | AD6: 0 | AE6: 0 | AF6: 0 | AG6: 0 | AH6: 0 | AI6: 0 | AJ6: 0 | AK6: 0 | AL6: 0 | AM6: 0 | AN6: 0 | AO6: 0 | AP6: 0 | AQ6: 0 | AR6: 0 | AS6: 0 | AT6: 0 | AU6: 0 | AV6: 0 | AW6: 0 | AX6: 0 | AY6: 0 | AZ6: 0 | BA6: 0 | BB6: 0 | BC6: 0 | BD6: 0 | BE6: 0 | BF6: 0 | BG6: 0 | BH6: 0 | BI6: 0 | BJ6: 0 | BK6: 0 | BL6: 0 | BM6: 0 | BN6: 0 | BO6: 0 | BP6: 0 | BQ6: 0 | BR6: 0 | BS6: 0 | BT6: 0 | BU6: 0 | BV6: 0 | BW6: 0 | BX6: 0 | BY6: 0 | BZ6: 0 | CA6: 0 | CB6: 0 | CC6: 0 | CD6: 0 | CE6: 0 | CF6: 0 | CG6: 0 | CH6: 0 | CI6: 0 | CJ6: 0 | CK6: 0 | CL6: 0 | CM6: 0 | CN6: 0 | CO6: 0 | CP6: 0 | CQ6: 0 | CR6: 0 | CS6: 0 | CT6: 0 | CU6: 0 | CV6: 0 | CW6: 0 | CX6: 0 | CY6: 0 | CZ6: 0 | DA6: 0 | DB6: 0 | DC6: 0 | DD6: 0 | DE6: 0 | DF6: 0 | DG6: 0 | DH6: 0 | DI6: 0 | DJ6: 0 | DK6: 0 | DL6: 0 | DM6: 0 | DN6: 0 | DO6: 0 | DP6: 0 | DQ6: 0 | DR6: 0 | DS6: 0 | DT6: 0 | DU6: 0 | DV6: 0 | DW6: 0 | DX6: 0 | DY6: 0 | DZ6: 0 | EA6: 0 | EB6: 0 | EC6: 0 | ED6: 0 | EE6: 0 | EF6: 0 | EG6: 0 | EH6: 0 | EI6: 0
A7: 가르시니아캄보지아 추출물 | B7: 검출건수 | C7: 0 | D7: 0 | E7: 0 | F7: 0 | G7: 0 | H7: 0 | I7: 0 | J7: 0 | K7: 0 | L7: 0 | M7: 0 | N7: 0 | O7: 0 | P7: 0 | Q7: 0 | R7: 0 | S7: 0 | T7: 0 | U7: 0 | V7: 0 | W7: 0 | X7: 0 | Y7: 0 | Z7: 0 | AA7: 0 | AB7: 0 | AC7: 0 | AD7: 0 | AE7: 0 | AF7: 0 | AG7: 0 | AH7: 0 | AI7: 0 | AJ7: 0 | AK7: 0 | AL7: 0 | AM7: 0 | AN7: 0 | AO7: 0 | AP7: 0 | AQ7: 0 | AR7: 0 | AS7: 0 | AT7: 0 | AU7: 0 | AV7: 0 | AW7: 0 | AX7: 0 | AY7: 0 | AZ7: 0 | BA7: 0 | BB7: 0 | BC7: 0 | BD7: 0 | BE7: 0 | BF7: 0 | BG7: 0 | BH7: 0 | BI7: 0 | BJ7: 0 | BK7: 0 | BL7: 0 | BM7: 0 | BN7: 0 | BO7: 0 | BP7: 0 | BQ7: 0 | BR7: 0 | BS7: 0 | BT7: 0 | BU7: 0 | BV7: 0 | BW7: 0 | BX7: 0 | BY7: 0 | BZ7: 0 | CA7: 0 | CB7: 0 | CC7: 0 | CD7: 0 | CE7: 0 | CF7: 0 | CG7: 0 | CH7: 0 | CI7: 0 | CJ7: 0 | CK7: 0 | CL7: 0 | CM7: 0 | CN7: 0 | CO7: 0 | CP7: 0 | CQ7: 0 | CR7: 0 | CS7: 0 | CT7: 0 | CU7: 0 | CV7: 0 | CW7: 0 | CX7: 0 | CY7: 0 | CZ7: 0 | DA7: 0 | DB7: 0 | DC7: 0 | DD7: 0 | DE7: 0 | DF7: 0 | DG7: 0 | DH7: 0 | DI7: 0 | DJ7: 0 | DK7: 0 | DL7: 0 | DM7: 0 | DN7: 0 | DO7: 0 | DP7: 0 | DQ7: 0 | DR7: 0 | DS7: 0 | DT7: 0 | DU7: 0 | DV7: 0 | DW7: 0 | DX7: 0 | DY7: 0 | DZ7: 0 | EA7: 0 | EB7: 0 | EC7: 0 | ED7: 0 | EE7: 0 | EF7: 0 | EG7: 0 | EH7: 0 | EI7: 0
A8: 감귤류 | B8: 검출건수 | C8: 0 | D8: 0 | E8: 0 | F8: 0 | G8: 0 | H8: 0 | I8: 0 | J8: 0 | K8: 0 | L8: 0 | M8: 0 | N8: 0 | O8: 0 | P8: 0 | Q8: 0 | R8: 0 | S8: 0 | T8: 0 | U8: 0 | V8: 0 | W8: 0 | X8: 0 | Y8: 0 | Z8: 0 | AA8: 0 | AB8: 0 | AC8: 0 | AD8: 0 | AE8: 0 | AF8: 0 | AG8: 0 | AH8: 0 | AI8: 0 | AJ8: 0 | AK8: 0 | AL8: 0 | AM8: 0 | AN8: 0 | AO8: 0 | AP8: 0 | AQ8: 0 | AR8: 0 | AS8: 0 | AT8: 0 | AU8: 0 | AV8: 0 | AW8: 0 | AX8: 0 | AY8: 0 | AZ8: 0 | BA8: 0 | BB8: 0 | BC8: 0 | BD8: 0 | BE8: 0 | BF8: 0 | BG8: 0 | BH8: 0 | BI8: 0 | BJ8: 0 | BK8: 0 | BL8: 0 | BM8: 0 | BN8: 0 | BO8: 0 | BP8: 0 | BQ8: 0 | BR8: 0 | BS8: 0 | BT8: 0 | BU8: 0 | BV8: 0 | BW8: 0 | BX8: 0 | BY8: 0 | BZ8: 0 | CA8: 0 | CB8: 0 | CC8: 0 | CD8: 0 | CE8: 0 | CF8: 0 | CG8: 0 | CH8: 0 | CI8: 0 | CJ8: 0 | CK8: 0 | CL8: 0 | CM8: 0 | CN8: 0 | CO8: 0 | CP8: 0 | CQ8: 0 | CR8: 0 | CS8: 0 | CT8: 0 | CU8: 0 | CV8: 0 | CW8: 0 | CX8: 0 | CY8: 0 | CZ8: 0 | DA8: 0 | DB8: 0 | DC8: 0 | DD8: 0 | DE8: 0 | DF8: 0 | DG8: 0 | DH8: 0 | DI8: 0 | DJ8: 0 | DK8: 0 | DL8: 0 | DM8: 0 | DN8: 0 | DO8: 0 | DP8: 0 | DQ8: 0 | DR8: 0 | DS8: 0 | DT8: 0 | DU8: 0 | DV8: 0 | DW8: 0 | DX8: 0 | DY8: 0 | DZ8: 0 | EA8: 0 | EB8: 0 | EC8: 0 | ED8: 0 | EE8: 0 | EF8: 0 | EG8: 0 | EH8: 0 | EI8: 0
A9: 감자 | B9: 검출건수 | C9: 0 | D9: 0 | E9: 0 | F9: 0 | G9: 0 | H9: 0 | I9: 0 | J9: 0 | K9: 0 | L9: 0 | M9: 0 | N9: 0 | O9: 0 | P9: 0 | Q9: 0 | R9: 0 | S9: 0 | T9: 0 | U9: 0 | V9: 0 | W9: 0 | X9: 0 | Y9: 0 | Z9: 0 | AA9: 0 | AB9: 0 | AC9: 0 | AD9: 0 | AE9: 0 | AF9: 0 | AG9: 0 | AH9: 0 | AI9: 0 | AJ9: 0 | AK9: 0 | AL9: 0 | AM9: 0 | AN9: 0 | AO9: 0 | AP9: 0 | AQ9: 0 | AR9: 0 | AS9: 0 | AT9: 0 | AU9: 0 | AV9: 0 | AW9: 0 | AX9: 0 | AY9: 0 | AZ9: 0 | BA9: 0 | BB9: 0 | BC9: 0 | BD9: 0 | BE9: 0 | BF9: 0 | BG9: 0 | BH9: 0 | BI9: 0 | BJ9: 0 | BK9: 0 | BL9: 0 | BM9: 0 | BN9: 0 | BO9: 0 | BP9: 0 | BQ9: 0 | BR9: 0 | BS9: 0 | BT9: 0 | BU9: 0 | BV9: 0 | BW9: 0 | BX9: 0 | BY9: 0 | BZ9: 0 | CA9: 0 | CB9: 0 | CC9: 0 | CD9: 0 | CE9: 0 | CF9: 0 | CG9: 0 | CH9: 0 | CI9: 0 | CJ9: 0 | CK9: 0 | CL9: 0 | CM9: 0 | CN9: 0 | CO9: 0 | CP9: 0 | CQ9: 0 | CR9: 0 | CS9: 0 | CT9: 0 | CU9: 0 | CV9: 0 | CW9: 0 | CX9: 0 | CY9: 0 | CZ9: 0 | DA9: 0 | DB9: 0 | DC9: 0 | DD9: 0 | DE9: 0 | DF9: 0 | DG9: 0 | DH9: 0 | DI9: 0 | DJ9: 0 | DK9: 0 | DL9: 0 | DM9: 0 | DN9: 0 | DO9: 0 | DP9: 0 | DQ9: 0 | DR9: 0 | DS9: 0 | DT9: 0 | DU9: 0 | DV9: 0 | DW9: 0 | DX9: 0 | DY9: 0 | DZ9: 0 | EA9: 0 | EB9: 0 | EC9: 0 | ED9: 0 | EE9: 0 | EF9: 0 | EG9: 0 | EH9: 0 | EI9: 0
A10: 갑각류 | B10: 검출건수 | C10: 0 | D10: 0 | E10: 0 | F10: 0 | G10: 0 | H10: 0 | I10: 0 | J10: 0 | K10: 0 | L10: 0 | M10: 0 | N10: 0 | O10: 0 | P10: 0 | Q10: 0 | R10: 0 | S10: 0 | T10: 0 | U10: 0 | V10: 0 | W10: 0 | X10: 0 | Y10: 0 | Z10: 0 | AA10: 0 | AB10: 0 | AC10: 0 | AD10: 0 | AE10: 0 | AF10: 0 | AG10: 0 | AH10: 0 | AI10: 0 | AJ10: 0 | AK10: 0 | AL10: 0 | AM10: 0 | AN10: 0 | AO10: 0 | AP10: 0 | AQ10: 0 | AR10: 0 | AS10: 0 | AT10: 0 | AU10: 0 | AV10: 0 | AW10: 0 | AX10: 0 | AY10: 0 | AZ10: 0 | BA10: 0 | BB10: 0 | BC10: 0 | BD10: 0 | BE10: 0 | BF10: 0 | BG10: 0 | BH10: 0 | BI10: 0 | BJ10: 0 | BK10: 0 | BL10: 0 | BM10: 0 | BN10: 0 | BO10: 0 | BP10: 0 | BQ10: 0 | BR10: 0 | BS10: 0 | BT10: 0 | BU10: 0 | BV10: 0 | BW10: 0 | BX10: 0 | BY10: 1 | BZ10: 0 | CA10: 0 | CB10: 0 | CC10: 0 | CD10: 0 | CE10: 0 | CF10: 0 | CG10: 0 | CH10: 0 | CI10: 0 | CJ10: 0 | CK10: 0 | CL10: 0 | CM10: 0 | CN10: 0 | CO10: 0 | CP10: 0 | CQ10: 0 | CR10: 0 | CS10: 0 | CT10: 0 | CU10: 0 | CV10: 0 | CW10: 0 | CX10: 0 | CY10: 0 | CZ10: 0 | DA10: 0 | DB10: 0 | DC10: 0 | DD10: 0 | DE10: 0 | DF10: 0 | DG10: 0 | DH10: 0 | DI10: 0 | DJ10: 0 | DK10: 0 | DL10: 0 | DM10: 0 | DN10: 0 | DO10: 0 | DP10: 0 | DQ10: 0 | DR10: 0 | DS10: 0 | DT10: 0 | DU10: 0 | DV10: 0 | DW10: 0 | DX10: 0 | DY10: 0 | DZ10: 0 | EA10: 0 | EB10: 0 | EC10: 0 | ED10: 0 | EE10: 0 | EF10: 0 | EG10: 0 | EH10: 0 | EI10: 0
A11: 개별인정원료 | B11: 검출건수 | C11: 0 | D11: 0 | E11: 0 | F11: 0 | G11: 0 | H11: 0 | I11: 0 | J11: 0 | K11: 0 | L11: 0 | M11: 0 | N11: 0 | O11: 0 | P11: 0 | Q11: 0 | R11: 0 | S11: 0 | T11: 0 | U11: 0 | V11: 0 | W11: 0 | X11: 0 | Y11: 0 | Z11: 0 | AA11: 0 | AB11: 0 | AC11: 0 | AD11: 0 | AE11: 0 | AF11: 0 | AG11: 0 | AH11: 0 | AI11: 0 | AJ11: 0 | AK11: 0 | AL11: 0 | AM11: 0 | AN11: 0 | AO11: 0 | AP11: 0 | AQ11: 0 | AR11: 0 | AS11: 0 | AT11: 0 | AU11: 0 | AV11: 0 | AW11: 0 | AX11: 0 | AY11: 0 | AZ11: 0 | BA11: 0 | BB11: 0 | BC11: 0 | BD11: 0 | BE11: 0 | BF11: 0 | BG11: 0 | BH11: 0 | BI11: 0 | BJ11: 0 | BK11: 0 | BL11: 0 | BM11: 0 | BN11: 0 | BO11: 0 | BP11: 0 | BQ11: 0 | BR11: 0 | BS11: 0 | BT11: 0 | BU11: 0 | BV11: 0 | BW11: 0 | BX11: 0 | BY11: 0 | BZ11: 0 | CA11: 0 | CB11: 0 | CC11: 0 | CD11: 0 | CE11: 0 | CF11: 0 | CG11: 0 | CH11: 0 | CI11: 0 | CJ11: 0 | CK11: 0 | CL11: 0 | CM11: 0 | CN11: 0 | CO11: 0 | CP11: 0 | CQ11: 0 | CR11: 0 | CS11: 0 | CT11: 0 | CU11: 0 | CV11: 0 | CW11: 0 | CX11: 0 | CY11: 0 | CZ11: 0 | DA11: 0 | DB11: 0 | DC11: 0 | DD11: 0 | DE11: 0 | DF11: 0 | DG11: 0 | DH11: 0 | DI11: 0 | DJ11: 0 | DK11: 0 | DL11: 0 | DM11: 0 | DN11: 0 | DO11: 0 | DP11: 0 | DQ11: 0 | DR11: 0 | DS11: 0 | DT11: 0 | DU11: 0 | DV11: 0 | DW11: 0 | DX11: 0 | DY11: 0 | DZ11: 0 | EA11: 0 | EB11: 0 | EC11: 0 | ED11: 0 | EE11: 0 | EF11: 0 | EG11: 0 | EH11: 0 | EI11: 0
